{
    DataVersion: 2730,
    size: [8, 10, 8],
    data: [
        {pos: [0, 0, 7], state: "minecraft:air"},
        {pos: [2, 0, 2], state: "minecraft:dirt"},
        {pos: [2, 0, 3], state: "minecraft:dirt"},
        {pos: [2, 0, 4], state: "minecraft:dirt"},
        {pos: [3, 0, 2], state: "minecraft:dirt"},
        {pos: [3, 0, 3], state: "minecraft:dirt"},
        {pos: [3, 0, 4], state: "minecraft:dirt"},
        {pos: [4, 0, 2], state: "minecraft:dirt"},
        {pos: [4, 0, 3], state: "minecraft:dirt"},
        {pos: [4, 0, 4], state: "minecraft:dirt"},
        {pos: [5, 0, 2], state: "minecraft:dirt"},
        {pos: [5, 0, 3], state: "minecraft:dirt"},
        {pos: [5, 0, 4], state: "minecraft:dirt"},
        {pos: [5, 0, 5], state: "minecraft:dirt"},
        {pos: [5, 0, 6], state: "minecraft:dirt"},
        {pos: [5, 0, 7], state: "minecraft:dirt"},
        {pos: [6, 0, 2], state: "minecraft:dirt"},
        {pos: [6, 0, 3], state: "minecraft:dirt"},
        {pos: [6, 0, 4], state: "minecraft:dirt"},
        {pos: [6, 0, 5], state: "minecraft:dirt"},
        {pos: [6, 0, 6], state: "minecraft:dirt"},
        {pos: [6, 0, 7], state: "minecraft:dirt"},
        {pos: [7, 0, 2], state: "minecraft:dirt"},
        {pos: [7, 0, 3], state: "minecraft:dirt"},
        {pos: [7, 0, 4], state: "minecraft:dirt"},
        {pos: [7, 0, 5], state: "minecraft:dirt"},
        {pos: [7, 0, 6], state: "minecraft:dirt"},
        {pos: [7, 0, 7], state: "minecraft:dirt"},
        {pos: [0, 1, 7], state: "minecraft:air"},
        {pos: [2, 1, 2], state: "minecraft:dirt"},
        {pos: [2, 1, 3], state: "minecraft:dirt"},
        {pos: [2, 1, 4], state: "minecraft:dirt"},
        {pos: [3, 1, 2], state: "minecraft:dirt"},
        {pos: [3, 1, 3], state: "minecraft:dirt"},
        {pos: [3, 1, 4], state: "minecraft:dirt"},
        {pos: [4, 1, 2], state: "minecraft:dirt"},
        {pos: [4, 1, 3], state: "minecraft:dirt"},
        {pos: [4, 1, 4], state: "minecraft:dirt"},
        {pos: [5, 1, 2], state: "minecraft:dirt"},
        {pos: [5, 1, 3], state: "minecraft:dirt"},
        {pos: [5, 1, 4], state: "minecraft:dirt"},
        {pos: [5, 1, 5], state: "minecraft:dirt"},
        {pos: [5, 1, 6], state: "minecraft:dirt"},
        {pos: [5, 1, 7], state: "minecraft:dirt"},
        {pos: [6, 1, 2], state: "minecraft:dirt"},
        {pos: [6, 1, 3], state: "minecraft:dirt"},
        {pos: [6, 1, 4], state: "minecraft:dirt"},
        {pos: [6, 1, 5], state: "minecraft:dirt"},
        {pos: [6, 1, 6], state: "minecraft:dirt"},
        {pos: [6, 1, 7], state: "minecraft:dirt"},
        {pos: [7, 1, 2], state: "minecraft:dirt"},
        {pos: [7, 1, 3], state: "minecraft:dirt"},
        {pos: [7, 1, 4], state: "minecraft:dirt"},
        {pos: [7, 1, 5], state: "minecraft:dirt"},
        {pos: [7, 1, 6], state: "minecraft:dirt"},
        {pos: [7, 1, 7], state: "minecraft:dirt"},
        {pos: [0, 2, 7], state: "minecraft:air"},
        {pos: [2, 2, 2], state: "minecraft:dirt"},
        {pos: [2, 2, 3], state: "minecraft:grass_block{snowy:false}"},
        {pos: [2, 2, 4], state: "minecraft:grass_block{snowy:false}"},
        {pos: [3, 2, 2], state: "minecraft:grass_block{snowy:false}"},
        {pos: [3, 2, 3], state: "minecraft:grass_block{snowy:false}"},
        {pos: [3, 2, 4], state: "minecraft:grass_block{snowy:false}"},
        {pos: [4, 2, 2], state: "minecraft:grass_block{snowy:false}"},
        {pos: [4, 2, 3], state: "minecraft:grass_block{snowy:false}"},
        {pos: [4, 2, 4], state: "minecraft:grass_block{snowy:false}"},
        {pos: [5, 2, 2], state: "minecraft:grass_block{snowy:false}"},
        {pos: [5, 2, 3], state: "minecraft:grass_block{snowy:false}"},
        {pos: [5, 2, 4], state: "minecraft:grass_block{snowy:false}"},
        {pos: [5, 2, 5], state: "minecraft:grass_block{snowy:false}"},
        {pos: [5, 2, 6], state: "minecraft:grass_block{snowy:false}"},
        {pos: [5, 2, 7], state: "minecraft:grass_block{snowy:false}"},
        {pos: [6, 2, 2], state: "minecraft:grass_block{snowy:false}"},
        {pos: [6, 2, 3], state: "minecraft:grass_block{snowy:false}"},
        {pos: [6, 2, 4], state: "minecraft:grass_block{snowy:false}"},
        {pos: [6, 2, 5], state: "minecraft:grass_block{snowy:false}"},
        {pos: [6, 2, 6], state: "minecraft:grass_block{snowy:false}"},
        {pos: [6, 2, 7], state: "minecraft:grass_block{snowy:false}"},
        {pos: [7, 2, 2], state: "minecraft:grass_block{snowy:false}"},
        {pos: [7, 2, 3], state: "minecraft:grass_block{snowy:false}"},
        {pos: [7, 2, 4], state: "minecraft:grass_block{snowy:false}"},
        {pos: [7, 2, 5], state: "minecraft:grass_block{snowy:false}"},
        {pos: [7, 2, 6], state: "minecraft:grass_block{snowy:false}"},
        {pos: [7, 2, 7], state: "minecraft:grass_block{snowy:false}"},
        {pos: [0, 3, 7], state: "minecraft:air"},
        {pos: [2, 3, 2], state: "minecraft:oak_log{axis:y}"},
        {pos: [6, 3, 7], state: "minecraft:chest{facing:north,type:single,waterlogged:false}", nbt: {Items: [{Count: 1b, Slot: 0b, id: "minecraft:ice"}, {Count: 1b, Slot: 1b, id: "minecraft:lava_bucket"}, {Count: 32b, Slot: 2b, id: "minecraft:sand"}, {Count: 1b, Slot: 9b, id: "minecraft:melon_slice"}, {Count: 1b, Slot: 10b, id: "minecraft:pumpkin_seeds"}, {Count: 1b, Slot: 11b, id: "minecraft:sugar_cane"}, {Count: 1b, Slot: 12b, id: "minecraft:cactus"}, {Count: 1b, Slot: 20b, id: "minecraft:bamboo"}, {Count: 10b, Slot: 26b, id: "minecraft:obsidian"}], id: "minecraft:chest"}},
        {pos: [0, 4, 7], state: "minecraft:air"},
        {pos: [2, 4, 2], state: "minecraft:oak_log{axis:y}"},
        {pos: [0, 5, 7], state: "minecraft:air"},
        {pos: [2, 5, 2], state: "minecraft:oak_log{axis:y}"},
        {pos: [0, 6, 1], state: "minecraft:oak_leaves{distance:3,persistent:false}"},
        {pos: [0, 6, 2], state: "minecraft:oak_leaves{distance:2,persistent:false}"},
        {pos: [0, 6, 3], state: "minecraft:oak_leaves{distance:3,persistent:false}"},
        {pos: [0, 6, 4], state: "minecraft:oak_leaves{distance:4,persistent:false}"},
        {pos: [0, 6, 7], state: "minecraft:air"},
        {pos: [1, 6, 0], state: "minecraft:oak_leaves{distance:3,persistent:false}"},
        {pos: [1, 6, 1], state: "minecraft:oak_leaves{distance:2,persistent:false}"},
        {pos: [1, 6, 2], state: "minecraft:oak_leaves{distance:1,persistent:false}"},
        {pos: [1, 6, 3], state: "minecraft:oak_leaves{distance:2,persistent:false}"},
        {pos: [1, 6, 4], state: "minecraft:oak_leaves{distance:3,persistent:false}"},
        {pos: [2, 6, 0], state: "minecraft:oak_leaves{distance:2,persistent:false}"},
        {pos: [2, 6, 1], state: "minecraft:oak_leaves{distance:1,persistent:false}"},
        {pos: [2, 6, 2], state: "minecraft:oak_log{axis:y}"},
        {pos: [2, 6, 3], state: "minecraft:oak_leaves{distance:1,persistent:false}"},
        {pos: [2, 6, 4], state: "minecraft:oak_leaves{distance:2,persistent:false}"},
        {pos: [3, 6, 0], state: "minecraft:oak_leaves{distance:3,persistent:false}"},
        {pos: [3, 6, 1], state: "minecraft:oak_leaves{distance:2,persistent:false}"},
        {pos: [3, 6, 2], state: "minecraft:oak_leaves{distance:1,persistent:false}"},
        {pos: [3, 6, 3], state: "minecraft:oak_leaves{distance:2,persistent:false}"},
        {pos: [3, 6, 4], state: "minecraft:oak_leaves{distance:3,persistent:false}"},
        {pos: [4, 6, 0], state: "minecraft:oak_leaves{distance:4,persistent:false}"},
        {pos: [4, 6, 1], state: "minecraft:oak_leaves{distance:3,persistent:false}"},
        {pos: [4, 6, 2], state: "minecraft:oak_leaves{distance:2,persistent:false}"},
        {pos: [4, 6, 3], state: "minecraft:oak_leaves{distance:3,persistent:false}"},
        {pos: [4, 6, 4], state: "minecraft:oak_leaves{distance:4,persistent:false}"},
        {pos: [0, 7, 0], state: "minecraft:oak_leaves{distance:4,persistent:false}"},
        {pos: [0, 7, 1], state: "minecraft:oak_leaves{distance:3,persistent:false}"},
        {pos: [0, 7, 2], state: "minecraft:oak_leaves{distance:2,persistent:false}"},
        {pos: [0, 7, 3], state: "minecraft:oak_leaves{distance:3,persistent:false}"},
        {pos: [0, 7, 7], state: "minecraft:air"},
        {pos: [1, 7, 0], state: "minecraft:oak_leaves{distance:3,persistent:false}"},
        {pos: [1, 7, 1], state: "minecraft:oak_leaves{distance:2,persistent:false}"},
        {pos: [1, 7, 2], state: "minecraft:oak_leaves{distance:1,persistent:false}"},
        {pos: [1, 7, 3], state: "minecraft:oak_leaves{distance:2,persistent:false}"},
        {pos: [1, 7, 4], state: "minecraft:oak_leaves{distance:3,persistent:false}"},
        {pos: [2, 7, 0], state: "minecraft:oak_leaves{distance:2,persistent:false}"},
        {pos: [2, 7, 1], state: "minecraft:oak_leaves{distance:1,persistent:false}"},
        {pos: [2, 7, 2], state: "minecraft:oak_log{axis:y}"},
        {pos: [2, 7, 3], state: "minecraft:oak_leaves{distance:1,persistent:false}"},
        {pos: [2, 7, 4], state: "minecraft:oak_leaves{distance:2,persistent:false}"},
        {pos: [3, 7, 0], state: "minecraft:oak_leaves{distance:3,persistent:false}"},
        {pos: [3, 7, 1], state: "minecraft:oak_leaves{distance:2,persistent:false}"},
        {pos: [3, 7, 2], state: "minecraft:oak_leaves{distance:1,persistent:false}"},
        {pos: [3, 7, 3], state: "minecraft:oak_leaves{distance:2,persistent:false}"},
        {pos: [3, 7, 4], state: "minecraft:oak_leaves{distance:3,persistent:false}"},
        {pos: [4, 7, 0], state: "minecraft:oak_leaves{distance:4,persistent:false}"},
        {pos: [4, 7, 1], state: "minecraft:oak_leaves{distance:3,persistent:false}"},
        {pos: [4, 7, 2], state: "minecraft:oak_leaves{distance:2,persistent:false}"},
        {pos: [4, 7, 3], state: "minecraft:oak_leaves{distance:3,persistent:false}"},
        {pos: [0, 8, 7], state: "minecraft:air"},
        {pos: [1, 8, 2], state: "minecraft:oak_leaves{distance:1,persistent:false}"},
        {pos: [2, 8, 1], state: "minecraft:oak_leaves{distance:1,persistent:false}"},
        {pos: [2, 8, 2], state: "minecraft:oak_log{axis:y}"},
        {pos: [2, 8, 3], state: "minecraft:oak_leaves{distance:1,persistent:false}"},
        {pos: [3, 8, 2], state: "minecraft:oak_leaves{distance:1,persistent:false}"},
        {pos: [3, 8, 3], state: "minecraft:oak_leaves{distance:2,persistent:false}"},
        {pos: [0, 9, 7], state: "minecraft:air"},
        {pos: [1, 9, 2], state: "minecraft:oak_leaves{distance:2,persistent:false}"},
        {pos: [2, 9, 1], state: "minecraft:oak_leaves{distance:2,persistent:false}"},
        {pos: [2, 9, 2], state: "minecraft:oak_leaves{distance:1,persistent:false}"},
        {pos: [2, 9, 3], state: "minecraft:oak_leaves{distance:2,persistent:false}"},
        {pos: [3, 9, 2], state: "minecraft:oak_leaves{distance:2,persistent:false}"}
    ],
    entities: [],
    palette: [
        "minecraft:dirt",
        "minecraft:grass_block{snowy:false}",
        "minecraft:oak_log{axis:y}",
        "minecraft:oak_leaves{distance:3,persistent:false}",
        "minecraft:oak_leaves{distance:2,persistent:false}",
        "minecraft:oak_leaves{distance:4,persistent:false}",
        "minecraft:oak_leaves{distance:1,persistent:false}",
        "minecraft:air",
        "minecraft:chest{facing:north,type:single,waterlogged:false}"
    ]
}