{
    DataVersion: 3465,
    size: [11, 5, 11],
    data: [
        {pos: [0, 0, 0], state: "minecraft:dirt"},
        {pos: [0, 0, 1], state: "minecraft:dirt"},
        {pos: [0, 0, 2], state: "minecraft:dirt"},
        {pos: [0, 0, 3], state: "minecraft:dirt"},
        {pos: [0, 0, 4], state: "minecraft:dirt"},
        {pos: [0, 0, 5], state: "minecraft:dirt"},
        {pos: [0, 0, 6], state: "minecraft:dirt"},
        {pos: [0, 0, 7], state: "minecraft:dirt"},
        {pos: [0, 0, 8], state: "minecraft:dirt"},
        {pos: [0, 0, 9], state: "minecraft:dirt"},
        {pos: [0, 0, 10], state: "minecraft:dirt"},
        {pos: [1, 0, 0], state: "minecraft:dirt"},
        {pos: [1, 0, 1], state: "minecraft:dirt"},
        {pos: [1, 0, 2], state: "minecraft:dirt"},
        {pos: [1, 0, 3], state: "minecraft:dirt"},
        {pos: [1, 0, 4], state: "minecraft:dirt"},
        {pos: [1, 0, 5], state: "mekanismadditions:black_reinforced_plastic"},
        {pos: [1, 0, 6], state: "minecraft:dirt"},
        {pos: [1, 0, 7], state: "minecraft:dirt"},
        {pos: [1, 0, 8], state: "minecraft:dirt"},
        {pos: [1, 0, 9], state: "minecraft:dirt"},
        {pos: [1, 0, 10], state: "minecraft:dirt"},
        {pos: [2, 0, 0], state: "minecraft:dirt"},
        {pos: [2, 0, 1], state: "minecraft:dirt"},
        {pos: [2, 0, 2], state: "minecraft:dirt"},
        {pos: [2, 0, 3], state: "minecraft:dirt"},
        {pos: [2, 0, 4], state: "mekanismadditions:black_reinforced_plastic"},
        {pos: [2, 0, 5], state: "mekanism:ultimate_universal_cable{fluid_logged:empty}", nbt: {connection0: 0, connection1: 0, connection2: 0, connection3: 0, connection4: 0, connection5: 0, energy: "8192000", id: "mekanism:ultimate_universal_cable", redstone: 0b}},
        {pos: [2, 0, 6], state: "mekanismadditions:black_reinforced_plastic"},
        {pos: [2, 0, 7], state: "minecraft:dirt"},
        {pos: [2, 0, 8], state: "minecraft:dirt"},
        {pos: [2, 0, 9], state: "minecraft:dirt"},
        {pos: [2, 0, 10], state: "minecraft:dirt"},
        {pos: [3, 0, 0], state: "minecraft:dirt"},
        {pos: [3, 0, 1], state: "minecraft:dirt"},
        {pos: [3, 0, 2], state: "minecraft:dirt"},
        {pos: [3, 0, 3], state: "minecraft:dirt"},
        {pos: [3, 0, 4], state: "mekanismadditions:black_reinforced_plastic"},
        {pos: [3, 0, 5], state: "mekanism:ultimate_universal_cable{fluid_logged:empty}", nbt: {connection0: 0, connection1: 0, connection2: 0, connection3: 0, connection4: 0, connection5: 0, energy: "8192000", id: "mekanism:ultimate_universal_cable", redstone: 0b}},
        {pos: [3, 0, 6], state: "mekanismadditions:black_reinforced_plastic"},
        {pos: [3, 0, 7], state: "minecraft:dirt"},
        {pos: [3, 0, 8], state: "minecraft:dirt"},
        {pos: [3, 0, 9], state: "minecraft:dirt"},
        {pos: [3, 0, 10], state: "minecraft:dirt"},
        {pos: [4, 0, 0], state: "minecraft:dirt"},
        {pos: [4, 0, 1], state: "minecraft:dirt"},
        {pos: [4, 0, 2], state: "minecraft:dirt"},
        {pos: [4, 0, 3], state: "minecraft:dirt"},
        {pos: [4, 0, 4], state: "minecraft:dirt"},
        {pos: [4, 0, 5], state: "mekanism:ultimate_universal_cable{fluid_logged:empty}", nbt: {connection0: 0, connection1: 0, connection2: 0, connection3: 0, connection4: 0, connection5: 0, energy: "8192000", id: "mekanism:ultimate_universal_cable", redstone: 0b}},
        {pos: [4, 0, 6], state: "minecraft:dirt"},
        {pos: [4, 0, 7], state: "minecraft:dirt"},
        {pos: [4, 0, 8], state: "minecraft:dirt"},
        {pos: [4, 0, 9], state: "minecraft:dirt"},
        {pos: [4, 0, 10], state: "minecraft:dirt"},
        {pos: [5, 0, 0], state: "minecraft:dirt"},
        {pos: [5, 0, 1], state: "mekanism:ultimate_universal_cable{fluid_logged:empty}", nbt: {connection0: 0, connection1: 0, connection2: 0, connection3: 0, connection4: 0, connection5: 0, energy: "8192000", id: "mekanism:ultimate_universal_cable", redstone: 0b}},
        {pos: [5, 0, 2], state: "mekanism:ultimate_universal_cable{fluid_logged:empty}", nbt: {connection0: 0, connection1: 0, connection2: 0, connection3: 0, connection4: 0, connection5: 0, energy: "8192000", id: "mekanism:ultimate_universal_cable", redstone: 0b}},
        {pos: [5, 0, 3], state: "mekanism:ultimate_universal_cable{fluid_logged:empty}", nbt: {connection0: 0, connection1: 0, connection2: 0, connection3: 0, connection4: 0, connection5: 0, energy: "8192000", id: "mekanism:ultimate_universal_cable", redstone: 0b}},
        {pos: [5, 0, 4], state: "mekanism:ultimate_universal_cable{fluid_logged:empty}", nbt: {connection0: 0, connection1: 0, connection2: 0, connection3: 0, connection4: 0, connection5: 0, energy: "8192000", id: "mekanism:ultimate_universal_cable", redstone: 0b}},
        {pos: [5, 0, 5], state: "mekanism:ultimate_universal_cable{fluid_logged:empty}", nbt: {connection0: 0, connection1: 0, connection2: 0, connection3: 0, connection4: 0, connection5: 0, energy: "8192000", id: "mekanism:ultimate_universal_cable", redstone: 0b}},
        {pos: [5, 0, 6], state: "mekanism:ultimate_universal_cable{fluid_logged:empty}", nbt: {connection0: 0, connection1: 0, connection2: 0, connection3: 0, connection4: 0, connection5: 0, energy: "8192000", id: "mekanism:ultimate_universal_cable", redstone: 0b}},
        {pos: [5, 0, 7], state: "mekanism:ultimate_universal_cable{fluid_logged:empty}", nbt: {connection0: 0, connection1: 0, connection2: 0, connection3: 0, connection4: 0, connection5: 0, energy: "8192000", id: "mekanism:ultimate_universal_cable", redstone: 0b}},
        {pos: [5, 0, 8], state: "mekanism:ultimate_universal_cable{fluid_logged:empty}", nbt: {connection0: 0, connection1: 0, connection2: 0, connection3: 0, connection4: 0, connection5: 0, energy: "8192000", id: "mekanism:ultimate_universal_cable", redstone: 0b}},
        {pos: [5, 0, 9], state: "mekanism:ultimate_universal_cable{fluid_logged:empty}", nbt: {connection0: 0, connection1: 0, connection2: 0, connection3: 0, connection4: 0, connection5: 0, energy: "8192000", id: "mekanism:ultimate_universal_cable", redstone: 0b}},
        {pos: [5, 0, 10], state: "minecraft:dirt"},
        {pos: [6, 0, 0], state: "minecraft:dirt"},
        {pos: [6, 0, 1], state: "minecraft:dirt"},
        {pos: [6, 0, 2], state: "minecraft:dirt"},
        {pos: [6, 0, 3], state: "minecraft:dirt"},
        {pos: [6, 0, 4], state: "minecraft:dirt"},
        {pos: [6, 0, 5], state: "minecraft:dirt"},
        {pos: [6, 0, 6], state: "minecraft:dirt"},
        {pos: [6, 0, 7], state: "minecraft:dirt"},
        {pos: [6, 0, 8], state: "minecraft:dirt"},
        {pos: [6, 0, 9], state: "minecraft:dirt"},
        {pos: [6, 0, 10], state: "minecraft:dirt"},
        {pos: [7, 0, 0], state: "minecraft:dirt"},
        {pos: [7, 0, 1], state: "minecraft:dirt"},
        {pos: [7, 0, 2], state: "minecraft:dirt"},
        {pos: [7, 0, 3], state: "minecraft:dirt"},
        {pos: [7, 0, 4], state: "minecraft:dirt"},
        {pos: [7, 0, 5], state: "minecraft:dirt"},
        {pos: [7, 0, 6], state: "minecraft:dirt"},
        {pos: [7, 0, 7], state: "minecraft:dirt"},
        {pos: [7, 0, 8], state: "minecraft:dirt"},
        {pos: [7, 0, 9], state: "minecraft:dirt"},
        {pos: [7, 0, 10], state: "minecraft:dirt"},
        {pos: [8, 0, 0], state: "minecraft:dirt"},
        {pos: [8, 0, 1], state: "minecraft:dirt"},
        {pos: [8, 0, 2], state: "minecraft:dirt"},
        {pos: [8, 0, 3], state: "minecraft:dirt"},
        {pos: [8, 0, 4], state: "minecraft:dirt"},
        {pos: [8, 0, 5], state: "minecraft:dirt"},
        {pos: [8, 0, 6], state: "minecraft:dirt"},
        {pos: [8, 0, 7], state: "minecraft:dirt"},
        {pos: [8, 0, 8], state: "minecraft:dirt"},
        {pos: [8, 0, 9], state: "minecraft:dirt"},
        {pos: [8, 0, 10], state: "minecraft:dirt"},
        {pos: [9, 0, 0], state: "minecraft:dirt"},
        {pos: [9, 0, 1], state: "minecraft:dirt"},
        {pos: [9, 0, 2], state: "minecraft:dirt"},
        {pos: [9, 0, 3], state: "minecraft:dirt"},
        {pos: [9, 0, 4], state: "minecraft:dirt"},
        {pos: [9, 0, 5], state: "minecraft:dirt"},
        {pos: [9, 0, 6], state: "minecraft:dirt"},
        {pos: [9, 0, 7], state: "minecraft:dirt"},
        {pos: [9, 0, 8], state: "minecraft:dirt"},
        {pos: [9, 0, 9], state: "minecraft:dirt"},
        {pos: [9, 0, 10], state: "minecraft:dirt"},
        {pos: [10, 0, 0], state: "minecraft:dirt"},
        {pos: [10, 0, 1], state: "minecraft:dirt"},
        {pos: [10, 0, 2], state: "minecraft:dirt"},
        {pos: [10, 0, 3], state: "minecraft:dirt"},
        {pos: [10, 0, 4], state: "minecraft:dirt"},
        {pos: [10, 0, 5], state: "minecraft:dirt"},
        {pos: [10, 0, 6], state: "minecraft:dirt"},
        {pos: [10, 0, 7], state: "minecraft:dirt"},
        {pos: [10, 0, 8], state: "minecraft:dirt"},
        {pos: [10, 0, 9], state: "minecraft:dirt"},
        {pos: [10, 0, 10], state: "minecraft:dirt"},
        {pos: [0, 1, 0], state: "minecraft:dirt"},
        {pos: [0, 1, 1], state: "minecraft:dirt"},
        {pos: [0, 1, 2], state: "minecraft:dirt"},
        {pos: [0, 1, 3], state: "minecraft:dirt"},
        {pos: [0, 1, 4], state: "minecraft:dirt"},
        {pos: [0, 1, 5], state: "mekanismadditions:black_reinforced_plastic"},
        {pos: [0, 1, 6], state: "minecraft:dirt"},
        {pos: [0, 1, 7], state: "minecraft:dirt"},
        {pos: [0, 1, 8], state: "minecraft:dirt"},
        {pos: [0, 1, 9], state: "minecraft:dirt"},
        {pos: [0, 1, 10], state: "minecraft:dirt"},
        {pos: [1, 1, 0], state: "minecraft:dirt"},
        {pos: [1, 1, 1], state: "mekanismadditions:black_reinforced_plastic"},
        {pos: [1, 1, 2], state: "mekanismadditions:black_reinforced_plastic"},
        {pos: [1, 1, 3], state: "mekanismadditions:black_reinforced_plastic"},
        {pos: [1, 1, 4], state: "mekanismadditions:black_reinforced_plastic"},
        {pos: [1, 1, 5], state: "mekanism:ultimate_universal_cable{fluid_logged:empty}", nbt: {connection0: 0, connection1: 0, connection2: 0, connection3: 0, connection4: 0, connection5: 0, energy: "8192000", id: "mekanism:ultimate_universal_cable", redstone: 0b}},
        {pos: [1, 1, 6], state: "mekanismadditions:black_reinforced_plastic"},
        {pos: [1, 1, 7], state: "mekanismadditions:black_reinforced_plastic"},
        {pos: [1, 1, 8], state: "mekanismadditions:black_reinforced_plastic"},
        {pos: [1, 1, 9], state: "mekanismadditions:black_reinforced_plastic"},
        {pos: [1, 1, 10], state: "minecraft:dirt"},
        {pos: [2, 1, 0], state: "minecraft:dirt"},
        {pos: [2, 1, 1], state: "mekanismadditions:black_reinforced_plastic"},
        {pos: [2, 1, 2], state: "mekanismadditions:black_reinforced_plastic"},
        {pos: [2, 1, 3], state: "mekanismadditions:black_reinforced_plastic"},
        {pos: [2, 1, 4], state: "mekanismadditions:white_reinforced_plastic"},
        {pos: [2, 1, 5], state: "mekanism:ultimate_universal_cable{fluid_logged:empty}", nbt: {connection0: 0, connection1: 0, connection2: 0, connection3: 0, connection4: 0, connection5: 0, energy: "8192000", id: "mekanism:ultimate_universal_cable", redstone: 0b}},
        {pos: [2, 1, 6], state: "mekanismadditions:white_reinforced_plastic"},
        {pos: [2, 1, 7], state: "mekanismadditions:black_reinforced_plastic"},
        {pos: [2, 1, 8], state: "mekanismadditions:black_reinforced_plastic"},
        {pos: [2, 1, 9], state: "mekanismadditions:black_reinforced_plastic"},
        {pos: [2, 1, 10], state: "minecraft:dirt"},
        {pos: [3, 1, 0], state: "minecraft:dirt"},
        {pos: [3, 1, 1], state: "mekanismadditions:black_reinforced_plastic"},
        {pos: [3, 1, 2], state: "mekanismadditions:black_reinforced_plastic"},
        {pos: [3, 1, 3], state: "mekanismadditions:black_reinforced_plastic"},
        {pos: [3, 1, 4], state: "mekanismadditions:white_reinforced_plastic"},
        {pos: [3, 1, 5], state: "mekanismadditions:white_reinforced_plastic"},
        {pos: [3, 1, 6], state: "mekanismadditions:white_reinforced_plastic"},
        {pos: [3, 1, 7], state: "mekanismadditions:black_reinforced_plastic"},
        {pos: [3, 1, 8], state: "mekanismadditions:black_reinforced_plastic"},
        {pos: [3, 1, 9], state: "mekanismadditions:black_reinforced_plastic"},
        {pos: [3, 1, 10], state: "minecraft:dirt"},
        {pos: [4, 1, 0], state: "minecraft:dirt"},
        {pos: [4, 1, 1], state: "mekanismadditions:black_reinforced_plastic"},
        {pos: [4, 1, 2], state: "mekanismadditions:black_reinforced_plastic"},
        {pos: [4, 1, 3], state: "mekanismadditions:black_reinforced_plastic"},
        {pos: [4, 1, 4], state: "mekanismadditions:black_reinforced_plastic"},
        {pos: [4, 1, 5], state: "mekanismadditions:black_reinforced_plastic"},
        {pos: [4, 1, 6], state: "mekanismadditions:black_reinforced_plastic"},
        {pos: [4, 1, 7], state: "mekanismadditions:black_reinforced_plastic"},
        {pos: [4, 1, 8], state: "mekanismadditions:black_reinforced_plastic"},
        {pos: [4, 1, 9], state: "mekanismadditions:black_reinforced_plastic"},
        {pos: [4, 1, 10], state: "minecraft:dirt"},
        {pos: [5, 1, 0], state: "minecraft:dirt"},
        {pos: [5, 1, 1], state: "mekanism:ultimate_universal_cable{fluid_logged:empty}", nbt: {connection0: 0, connection1: 0, connection2: 0, connection3: 0, connection4: 0, connection5: 0, energy: "8192000", id: "mekanism:ultimate_universal_cable", redstone: 0b}},
        {pos: [5, 1, 2], state: "mekanismadditions:black_reinforced_plastic"},
        {pos: [5, 1, 3], state: "mekanismadditions:black_reinforced_plastic"},
        {pos: [5, 1, 4], state: "mekanismadditions:black_reinforced_plastic"},
        {pos: [5, 1, 5], state: "mekanism:creative_energy_cube{facing:south,fluid_logged:empty}", nbt: {EnergyContainers: [{Container: 0b, stored: "18446744073709551615.9999"}], Items: [], componentConfig: {config0: {side0: 4, side1: 4, side2: 4, side3: 4, side4: 4, side5: 4}, config6: {side0: 4, side1: 1, side2: 1, side3: 1, side4: 1, side5: 1}, eject0: 1b, eject6: 0b}, componentEjector: {color0: -1, color1: -1, color2: -1, color3: -1, color4: -1, color5: -1, strictInput: 0b}, componentFrequency: {Security: {name: "Security", owner: [I; -265032353, -257276231, -1206336954, -524834293], publicFreq: 1b}}, componentSecurity: {owner: [I; -265032353, -257276231, -1206336954, -524834293], securityMode: 0}, controlType: 0, currentRedstone: 15, id: "mekanism:creative_energy_cube", redstone: 0b}},
        {pos: [5, 1, 6], state: "mekanismadditions:black_reinforced_plastic"},
        {pos: [5, 1, 7], state: "mekanismadditions:black_reinforced_plastic"},
        {pos: [5, 1, 8], state: "mekanismadditions:black_reinforced_plastic"},
        {pos: [5, 1, 9], state: "mekanism:ultimate_universal_cable{fluid_logged:empty}", nbt: {connection0: 0, connection1: 0, connection2: 0, connection3: 0, connection4: 0, connection5: 0, energy: "8192000", id: "mekanism:ultimate_universal_cable", redstone: 0b}},
        {pos: [5, 1, 10], state: "minecraft:dirt"},
        {pos: [6, 1, 0], state: "minecraft:dirt"},
        {pos: [6, 1, 1], state: "mekanismadditions:black_reinforced_plastic"},
        {pos: [6, 1, 2], state: "mekanismadditions:black_reinforced_plastic"},
        {pos: [6, 1, 3], state: "mekanismadditions:black_reinforced_plastic"},
        {pos: [6, 1, 4], state: "mekanismadditions:black_reinforced_plastic"},
        {pos: [6, 1, 5], state: "mekanismadditions:black_reinforced_plastic"},
        {pos: [6, 1, 6], state: "mekanismadditions:black_reinforced_plastic"},
        {pos: [6, 1, 7], state: "mekanismadditions:black_reinforced_plastic"},
        {pos: [6, 1, 8], state: "mekanismadditions:black_reinforced_plastic"},
        {pos: [6, 1, 9], state: "mekanismadditions:black_reinforced_plastic"},
        {pos: [6, 1, 10], state: "minecraft:dirt"},
        {pos: [7, 1, 0], state: "minecraft:dirt"},
        {pos: [7, 1, 1], state: "mekanismadditions:black_reinforced_plastic"},
        {pos: [7, 1, 2], state: "mekanismadditions:black_reinforced_plastic"},
        {pos: [7, 1, 3], state: "mekanismadditions:black_reinforced_plastic"},
        {pos: [7, 1, 4], state: "mekanismadditions:black_reinforced_plastic"},
        {pos: [7, 1, 5], state: "mekanismadditions:black_reinforced_plastic"},
        {pos: [7, 1, 6], state: "mekanismadditions:black_reinforced_plastic"},
        {pos: [7, 1, 7], state: "mekanismadditions:black_reinforced_plastic"},
        {pos: [7, 1, 8], state: "mekanismadditions:black_reinforced_plastic"},
        {pos: [7, 1, 9], state: "mekanismadditions:black_reinforced_plastic"},
        {pos: [7, 1, 10], state: "minecraft:dirt"},
        {pos: [8, 1, 0], state: "minecraft:dirt"},
        {pos: [8, 1, 1], state: "mekanismadditions:black_reinforced_plastic"},
        {pos: [8, 1, 2], state: "mekanismadditions:black_reinforced_plastic"},
        {pos: [8, 1, 3], state: "mekanismadditions:black_reinforced_plastic"},
        {pos: [8, 1, 4], state: "mekanismadditions:black_reinforced_plastic"},
        {pos: [8, 1, 5], state: "mekanismadditions:black_reinforced_plastic"},
        {pos: [8, 1, 6], state: "mekanismadditions:black_reinforced_plastic"},
        {pos: [8, 1, 7], state: "mekanismadditions:black_reinforced_plastic"},
        {pos: [8, 1, 8], state: "mekanismadditions:black_reinforced_plastic"},
        {pos: [8, 1, 9], state: "mekanismadditions:black_reinforced_plastic"},
        {pos: [8, 1, 10], state: "minecraft:dirt"},
        {pos: [9, 1, 0], state: "minecraft:dirt"},
        {pos: [9, 1, 1], state: "mekanismadditions:black_reinforced_plastic"},
        {pos: [9, 1, 2], state: "mekanismadditions:black_reinforced_plastic"},
        {pos: [9, 1, 3], state: "mekanismadditions:black_reinforced_plastic"},
        {pos: [9, 1, 4], state: "mekanismadditions:black_reinforced_plastic"},
        {pos: [9, 1, 5], state: "mekanismadditions:black_reinforced_plastic"},
        {pos: [9, 1, 6], state: "mekanismadditions:black_reinforced_plastic"},
        {pos: [9, 1, 7], state: "mekanismadditions:black_reinforced_plastic"},
        {pos: [9, 1, 8], state: "mekanismadditions:black_reinforced_plastic"},
        {pos: [9, 1, 9], state: "mekanismadditions:black_reinforced_plastic"},
        {pos: [9, 1, 10], state: "minecraft:dirt"},
        {pos: [10, 1, 0], state: "minecraft:dirt"},
        {pos: [10, 1, 1], state: "minecraft:dirt"},
        {pos: [10, 1, 2], state: "minecraft:dirt"},
        {pos: [10, 1, 3], state: "minecraft:dirt"},
        {pos: [10, 1, 4], state: "minecraft:dirt"},
        {pos: [10, 1, 5], state: "minecraft:dirt"},
        {pos: [10, 1, 6], state: "minecraft:dirt"},
        {pos: [10, 1, 7], state: "minecraft:dirt"},
        {pos: [10, 1, 8], state: "minecraft:dirt"},
        {pos: [10, 1, 9], state: "minecraft:dirt"},
        {pos: [10, 1, 10], state: "minecraft:dirt"},
        {pos: [0, 2, 0], state: "mekanismadditions:white_plastic_glow"},
        {pos: [0, 2, 1], state: "mekanismadditions:white_plastic_glow"},
        {pos: [0, 2, 2], state: "mekanismadditions:white_plastic_glow"},
        {pos: [0, 2, 3], state: "mekanismadditions:gray_plastic_glow"},
        {pos: [0, 2, 4], state: "mekanismadditions:gray_plastic_glow"},
        {pos: [0, 2, 5], state: "mekanismadditions:white_reinforced_plastic"},
        {pos: [0, 2, 6], state: "mekanismadditions:gray_plastic_glow"},
        {pos: [0, 2, 7], state: "mekanismadditions:gray_plastic_glow"},
        {pos: [0, 2, 8], state: "mekanismadditions:white_plastic_glow"},
        {pos: [0, 2, 9], state: "mekanismadditions:white_plastic_glow"},
        {pos: [0, 2, 10], state: "mekanismadditions:white_plastic_glow"},
        {pos: [1, 2, 0], state: "mekanismadditions:white_plastic_glow"},
        {pos: [1, 2, 1], state: "mekanismadditions:black_plastic_glow"},
        {pos: [1, 2, 2], state: "mekanismadditions:black_plastic_glow"},
        {pos: [1, 2, 3], state: "mekanismadditions:light_gray_plastic_glow"},
        {pos: [1, 2, 4], state: "mekanismadditions:light_gray_plastic_glow_stairs{facing:west,fluid_logged_extension:empty,half:bottom,shape:straight,waterlogged:false}"},
        {pos: [1, 2, 5], state: "mekanism:ultimate_universal_cable{fluid_logged:empty}", nbt: {connection0: 0, connection1: 0, connection2: 0, connection3: 0, connection4: 0, connection5: 0, energy: "8192000", id: "mekanism:ultimate_universal_cable", redstone: 0b}},
        {pos: [1, 2, 6], state: "mekanismadditions:light_gray_plastic_glow_stairs{facing:west,fluid_logged_extension:empty,half:bottom,shape:straight,waterlogged:false}"},
        {pos: [1, 2, 7], state: "mekanismadditions:light_gray_plastic_glow"},
        {pos: [1, 2, 8], state: "mekanismadditions:black_plastic_glow"},
        {pos: [1, 2, 9], state: "mekanismadditions:black_plastic_glow"},
        {pos: [1, 2, 10], state: "mekanismadditions:white_plastic_glow"},
        {pos: [2, 2, 0], state: "mekanismadditions:white_plastic_glow"},
        {pos: [2, 2, 1], state: "mekanismadditions:black_plastic_glow"},
        {pos: [2, 2, 2], state: "mekanismadditions:black_plastic_glow"},
        {pos: [2, 2, 3], state: "mekanismadditions:light_gray_plastic_glow_stairs{facing:north,fluid_logged_extension:empty,half:bottom,shape:straight,waterlogged:false}"},
        {pos: [2, 2, 4], state: "mekanism:personal_chest{facing:east,fluid_logged:empty}", nbt: {Items: [], componentFrequency: {}, componentSecurity: {securityMode: 0}, id: "mekanism:personal_chest", redstone: 0b}},
        {pos: [2, 2, 5], state: "mekanism:chargepad{active:false,facing:east,fluid_logged:empty}", nbt: {EnergyContainers: [{Container: 0b, stored: "2048000"}], activeState: 0b, componentFrequency: {}, id: "mekanism:chargepad", redstone: 0b, updateDelay: 0}},
        {pos: [2, 2, 6], state: "adminshop:shop"},
        {pos: [2, 2, 7], state: "mekanismadditions:light_gray_plastic_glow_stairs{facing:south,fluid_logged_extension:empty,half:bottom,shape:straight,waterlogged:false}"},
        {pos: [2, 2, 8], state: "mekanismadditions:black_plastic_glow"},
        {pos: [2, 2, 9], state: "mekanismadditions:black_plastic_glow"},
        {pos: [2, 2, 10], state: "mekanismadditions:white_plastic_glow"},
        {pos: [3, 2, 0], state: "mekanismadditions:white_plastic_glow"},
        {pos: [3, 2, 1], state: "mekanismadditions:black_plastic_glow"},
        {pos: [3, 2, 2], state: "mekanismadditions:black_plastic_glow"},
        {pos: [3, 2, 3], state: "mekanismadditions:light_gray_plastic_glow_stairs{facing:north,fluid_logged_extension:empty,half:bottom,shape:straight,waterlogged:false}"},
        {pos: [3, 2, 4], state: "minecraft:air"},
        {pos: [3, 2, 5], state: "minecraft:air"},
        {pos: [3, 2, 6], state: "minecraft:air"},
        {pos: [3, 2, 7], state: "mekanismadditions:light_gray_plastic_glow_stairs{facing:south,fluid_logged_extension:empty,half:bottom,shape:straight,waterlogged:false}"},
        {pos: [3, 2, 8], state: "mekanismadditions:black_plastic_glow"},
        {pos: [3, 2, 9], state: "mekanism:ultimate_universal_cable{fluid_logged:empty}", nbt: {connection0: 0, connection1: 0, connection2: 0, connection3: 0, connection4: 0, connection5: 0, energy: "8192000", id: "mekanism:ultimate_universal_cable", redstone: 0b}},
        {pos: [3, 2, 10], state: "mekanismadditions:white_plastic_glow"},
        {pos: [4, 2, 0], state: "mekanismadditions:white_plastic_glow"},
        {pos: [4, 2, 1], state: "mekanismadditions:black_plastic_glow"},
        {pos: [4, 2, 2], state: "mekanismadditions:magenta_plastic_transparent"},
        {pos: [4, 2, 3], state: "mekanismadditions:magenta_plastic_transparent_stairs{facing:east,fluid_logged_extension:empty,half:bottom,shape:inner_left,waterlogged:false}"},
        {pos: [4, 2, 4], state: "mekanismadditions:magenta_plastic_transparent_stairs{facing:east,fluid_logged_extension:empty,half:bottom,shape:straight,waterlogged:false}"},
        {pos: [4, 2, 5], state: "mekanismadditions:magenta_plastic_transparent_stairs{facing:east,fluid_logged_extension:empty,half:bottom,shape:straight,waterlogged:false}"},
        {pos: [4, 2, 6], state: "mekanismadditions:magenta_plastic_transparent_stairs{facing:east,fluid_logged_extension:empty,half:bottom,shape:straight,waterlogged:false}"},
        {pos: [4, 2, 7], state: "mekanismadditions:magenta_plastic_transparent_stairs{facing:east,fluid_logged_extension:empty,half:bottom,shape:inner_right,waterlogged:false}"},
        {pos: [4, 2, 8], state: "mekanismadditions:magenta_plastic_transparent"},
        {pos: [4, 2, 9], state: "mekanism:ultimate_universal_cable{fluid_logged:empty}", nbt: {connection0: 0, connection1: 0, connection2: 0, connection3: 0, connection4: 0, connection5: 0, energy: "8192000", id: "mekanism:ultimate_universal_cable", redstone: 0b}},
        {pos: [4, 2, 10], state: "mekanismadditions:white_plastic_glow"},
        {pos: [5, 2, 0], state: "mekanismadditions:white_plastic_glow"},
        {pos: [5, 2, 1], state: "mekanism:ultimate_universal_cable{fluid_logged:empty}", nbt: {connection0: 0, connection1: 0, connection2: 0, connection3: 0, connection4: 0, connection5: 0, energy: "8192000", id: "mekanism:ultimate_universal_cable", redstone: 0b}},
        {pos: [5, 2, 2], state: "mekanismadditions:yellow_plastic_transparent"},
        {pos: [5, 2, 3], state: "mekanismadditions:yellow_plastic_transparent"},
        {pos: [5, 2, 4], state: "mekanismadditions:yellow_plastic_transparent"},
        {pos: [5, 2, 5], state: "mekanismadditions:yellow_plastic_transparent"},
        {pos: [5, 2, 6], state: "mekanismadditions:yellow_plastic_transparent"},
        {pos: [5, 2, 7], state: "mekanismadditions:yellow_plastic_transparent"},
        {pos: [5, 2, 8], state: "mekanismadditions:yellow_plastic_transparent"},
        {pos: [5, 2, 9], state: "mekanism:ultimate_universal_cable{fluid_logged:empty}", nbt: {connection0: 0, connection1: 0, connection2: 0, connection3: 0, connection4: 0, connection5: 0, energy: "8192000", id: "mekanism:ultimate_universal_cable", redstone: 0b}},
        {pos: [5, 2, 10], state: "mekanismadditions:white_plastic_glow"},
        {pos: [6, 2, 0], state: "mekanismadditions:white_plastic_glow"},
        {pos: [6, 2, 1], state: "mekanismadditions:black_plastic_glow"},
        {pos: [6, 2, 2], state: "mekanismadditions:magenta_plastic_transparent"},
        {pos: [6, 2, 3], state: "mekanismadditions:magenta_plastic_transparent"},
        {pos: [6, 2, 4], state: "mekanismadditions:magenta_plastic_transparent"},
        {pos: [6, 2, 5], state: "mekanismadditions:yellow_plastic_transparent"},
        {pos: [6, 2, 6], state: "mekanismadditions:magenta_plastic_transparent"},
        {pos: [6, 2, 7], state: "mekanismadditions:magenta_plastic_transparent"},
        {pos: [6, 2, 8], state: "mekanismadditions:magenta_plastic_transparent"},
        {pos: [6, 2, 9], state: "mekanism:ultimate_universal_cable{fluid_logged:empty}", nbt: {connection0: 0, connection1: 0, connection2: 0, connection3: 0, connection4: 0, connection5: 0, energy: "8192000", id: "mekanism:ultimate_universal_cable", redstone: 0b}},
        {pos: [6, 2, 10], state: "mekanismadditions:white_plastic_glow"},
        {pos: [7, 2, 0], state: "mekanismadditions:white_plastic_glow"},
        {pos: [7, 2, 1], state: "mekanismadditions:black_plastic_glow"},
        {pos: [7, 2, 2], state: "mekanismadditions:black_plastic_glow"},
        {pos: [7, 2, 3], state: "mekanismadditions:black_plastic_glow"},
        {pos: [7, 2, 4], state: "mekanismadditions:magenta_plastic_transparent"},
        {pos: [7, 2, 5], state: "mekanismadditions:yellow_plastic_transparent"},
        {pos: [7, 2, 6], state: "mekanismadditions:magenta_plastic_transparent"},
        {pos: [7, 2, 7], state: "mekanismadditions:black_plastic_glow"},
        {pos: [7, 2, 8], state: "mekanismadditions:black_plastic_glow"},
        {pos: [7, 2, 9], state: "mekanism:ultimate_universal_cable{fluid_logged:empty}", nbt: {connection0: 0, connection1: 0, connection2: 0, connection3: 0, connection4: 0, connection5: 0, energy: "8192000", id: "mekanism:ultimate_universal_cable", redstone: 0b}},
        {pos: [7, 2, 10], state: "mekanismadditions:white_plastic_glow"},
        {pos: [8, 2, 0], state: "mekanismadditions:white_plastic_glow"},
        {pos: [8, 2, 1], state: "mekanismadditions:black_plastic_glow"},
        {pos: [8, 2, 2], state: "mekanismadditions:black_plastic_glow"},
        {pos: [8, 2, 3], state: "mekanismadditions:black_plastic_glow"},
        {pos: [8, 2, 4], state: "mekanismadditions:magenta_plastic_transparent"},
        {pos: [8, 2, 5], state: "mekanismadditions:yellow_plastic_transparent"},
        {pos: [8, 2, 6], state: "mekanismadditions:magenta_plastic_transparent"},
        {pos: [8, 2, 7], state: "mekanismadditions:black_plastic_glow"},
        {pos: [8, 2, 8], state: "mekanismadditions:black_plastic_glow"},
        {pos: [8, 2, 9], state: "mekanismadditions:black_plastic_glow"},
        {pos: [8, 2, 10], state: "mekanismadditions:white_plastic_glow"},
        {pos: [9, 2, 0], state: "mekanismadditions:white_plastic_glow"},
        {pos: [9, 2, 1], state: "mekanismadditions:black_plastic_glow"},
        {pos: [9, 2, 2], state: "mekanismadditions:black_plastic_glow"},
        {pos: [9, 2, 3], state: "mekanismadditions:black_plastic_glow"},
        {pos: [9, 2, 4], state: "mekanismadditions:black_plastic_glow"},
        {pos: [9, 2, 5], state: "mekanismadditions:black_plastic_glow"},
        {pos: [9, 2, 6], state: "mekanismadditions:black_plastic_glow"},
        {pos: [9, 2, 7], state: "mekanismadditions:black_plastic_glow"},
        {pos: [9, 2, 8], state: "mekanismadditions:black_plastic_glow"},
        {pos: [9, 2, 9], state: "mekanismadditions:black_plastic_glow"},
        {pos: [9, 2, 10], state: "mekanismadditions:white_plastic_glow"},
        {pos: [10, 2, 0], state: "mekanismadditions:white_plastic_glow"},
        {pos: [10, 2, 1], state: "mekanismadditions:white_plastic_glow"},
        {pos: [10, 2, 2], state: "mekanismadditions:white_plastic_glow"},
        {pos: [10, 2, 3], state: "mekanismadditions:white_plastic_glow"},
        {pos: [10, 2, 4], state: "mekanismadditions:white_plastic_glow"},
        {pos: [10, 2, 5], state: "mekanismadditions:white_plastic_glow"},
        {pos: [10, 2, 6], state: "mekanismadditions:white_plastic_glow"},
        {pos: [10, 2, 7], state: "mekanismadditions:white_plastic_glow"},
        {pos: [10, 2, 8], state: "mekanismadditions:white_plastic_glow"},
        {pos: [10, 2, 9], state: "mekanismadditions:white_plastic_glow"},
        {pos: [10, 2, 10], state: "mekanismadditions:white_plastic_glow"},
        {pos: [0, 3, 0], state: "minecraft:air"},
        {pos: [0, 3, 1], state: "minecraft:air"},
        {pos: [0, 3, 2], state: "minecraft:air"},
        {pos: [0, 3, 3], state: "minecraft:air"},
        {pos: [0, 3, 4], state: "minecraft:air"},
        {pos: [0, 3, 5], state: "minecraft:air"},
        {pos: [0, 3, 6], state: "minecraft:air"},
        {pos: [0, 3, 7], state: "minecraft:air"},
        {pos: [0, 3, 8], state: "minecraft:air"},
        {pos: [0, 3, 9], state: "minecraft:air"},
        {pos: [0, 3, 10], state: "minecraft:air"},
        {pos: [1, 3, 0], state: "minecraft:air"},
        {pos: [1, 3, 1], state: "minecraft:air"},
        {pos: [1, 3, 2], state: "minecraft:air"},
        {pos: [1, 3, 3], state: "mekanismadditions:gray_plastic_glow"},
        {pos: [1, 3, 4], state: "mekanismadditions:gray_plastic_glow_stairs{facing:west,fluid_logged_extension:empty,half:top,shape:straight,waterlogged:false}"},
        {pos: [1, 3, 5], state: "mekanismadditions:light_gray_plastic_glow_stairs{facing:west,fluid_logged_extension:empty,half:top,shape:straight,waterlogged:false}"},
        {pos: [1, 3, 6], state: "mekanismadditions:gray_plastic_glow_stairs{facing:west,fluid_logged_extension:empty,half:top,shape:straight,waterlogged:false}"},
        {pos: [1, 3, 7], state: "mekanismadditions:gray_plastic_glow"},
        {pos: [1, 3, 8], state: "minecraft:air"},
        {pos: [1, 3, 9], state: "minecraft:air"},
        {pos: [1, 3, 10], state: "minecraft:air"},
        {pos: [2, 3, 0], state: "minecraft:air"},
        {pos: [2, 3, 1], state: "minecraft:air"},
        {pos: [2, 3, 2], state: "minecraft:air"},
        {pos: [2, 3, 3], state: "mekanismadditions:light_gray_plastic_glow_stairs{facing:north,fluid_logged_extension:empty,half:top,shape:straight,waterlogged:false}"},
        {pos: [2, 3, 4], state: "minecraft:air"},
        {pos: [2, 3, 5], state: "minecraft:air"},
        {pos: [2, 3, 6], state: "minecraft:air"},
        {pos: [2, 3, 7], state: "mekanismadditions:light_gray_plastic_glow_stairs{facing:south,fluid_logged_extension:empty,half:top,shape:straight,waterlogged:false}"},
        {pos: [2, 3, 8], state: "minecraft:air"},
        {pos: [2, 3, 9], state: "minecraft:air"},
        {pos: [2, 3, 10], state: "minecraft:air"},
        {pos: [3, 3, 0], state: "minecraft:air"},
        {pos: [3, 3, 1], state: "minecraft:air"},
        {pos: [3, 3, 2], state: "minecraft:air"},
        {pos: [3, 3, 3], state: "minecraft:air"},
        {pos: [3, 3, 4], state: "minecraft:air"},
        {pos: [3, 3, 5], state: "minecraft:air"},
        {pos: [3, 3, 6], state: "minecraft:air"},
        {pos: [3, 3, 7], state: "minecraft:air"},
        {pos: [3, 3, 8], state: "minecraft:air"},
        {pos: [3, 3, 9], state: "mekanism:ultimate_sawing_factory{active:false,facing:north,fluid_logged:empty}", nbt: {EnergyContainers: [{Container: 0b, stored: "900000"}], Items: [], activeState: 0b, componentConfig: {config0: {side0: 1, side1: 1, side2: 1, side3: 1, side4: 1, side5: 1}, config6: {side0: 1, side1: 1, side2: 4, side3: 8, side4: 1, side5: 1}, eject0: 0b, eject6: 0b}, componentEjector: {color0: -1, color1: -1, color2: -1, color3: -1, color4: -1, color5: -1, strictInput: 0b}, componentFrequency: {Security: {name: "Security", owner: [I; -265032353, -257276231, -1206336954, -524834293], publicFreq: 1b}}, componentSecurity: {owner: [I; -265032353, -257276231, -1206336954, -524834293], securityMode: 0}, componentUpgrade: {Items: [], upgrades: [{amount: 8, type: 0}, {amount: 8, type: 1}]}, controlType: 0, currentRedstone: 0, id: "mekanism:ultimate_sawing_factory", progress: [I; 0, 0, 0, 0, 0, 0, 0, 0, 0], redstone: 0b, sorting: 0b, updateDelay: 0}},
        {pos: [3, 3, 10], state: "minecraft:air"},
        {pos: [4, 3, 0], state: "minecraft:air"},
        {pos: [4, 3, 1], state: "minecraft:air"},
        {pos: [4, 3, 2], state: "minecraft:air"},
        {pos: [4, 3, 3], state: "minecraft:air"},
        {pos: [4, 3, 4], state: "minecraft:air"},
        {pos: [4, 3, 5], state: "minecraft:air"},
        {pos: [4, 3, 6], state: "minecraft:air"},
        {pos: [4, 3, 7], state: "minecraft:air"},
        {pos: [4, 3, 8], state: "minecraft:air"},
        {pos: [4, 3, 9], state: "mekanism:ultimate_crushing_factory{active:false,facing:north,fluid_logged:empty}", nbt: {EnergyContainers: [{Container: 0b, stored: "900000"}], Items: [], activeState: 0b, componentConfig: {config0: {side0: 1, side1: 1, side2: 1, side3: 1, side4: 1, side5: 1}, config6: {side0: 1, side1: 1, side2: 4, side3: 8, side4: 1, side5: 1}, eject0: 0b, eject6: 0b}, componentEjector: {color0: -1, color1: -1, color2: -1, color3: -1, color4: -1, color5: -1, strictInput: 0b}, componentFrequency: {Security: {name: "Security", owner: [I; -265032353, -257276231, -1206336954, -524834293], publicFreq: 1b}}, componentSecurity: {owner: [I; -265032353, -257276231, -1206336954, -524834293], securityMode: 0}, componentUpgrade: {Items: [], upgrades: [{amount: 8, type: 0}, {amount: 8, type: 1}]}, controlType: 0, currentRedstone: 0, id: "mekanism:ultimate_crushing_factory", progress: [I; 0, 0, 0, 0, 0, 0, 0, 0, 0], redstone: 0b, sorting: 0b, updateDelay: 0}},
        {pos: [4, 3, 10], state: "minecraft:air"},
        {pos: [5, 3, 0], state: "mekanism:ultimate_logistical_transporter{fluid_logged:empty}", nbt: {color: -1, connection0: 0, connection1: 0, connection2: 0, connection3: 0, connection4: 0, connection5: 0, id: "mekanism:ultimate_logistical_transporter", redstone: 0b}},
        {pos: [5, 3, 1], state: "mekanism:nutritional_liquifier{active:false,facing:south}", nbt: {EnergyContainers: [{Container: 0b, stored: "400000"}], FluidTanks: [{Tank: 0b, stored: {Amount: 9996, FluidName: "mekanism:nutritional_paste"}}], Items: [{Item: {Count: 64b, id: "minecraft:potato"}, Slot: 0b}, {Slot: 1b, draining: 1b}], activeState: 0b, componentConfig: {config0: {side0: 1, side1: 1, side2: 1, side3: 1, side4: 1, side5: 1}, config1: {side0: 0, side1: 0, side2: 4, side3: 0, side4: 0, side5: 0}, config6: {side0: 1, side1: 1, side2: 4, side3: 1, side4: 1, side5: 1}, eject0: 0b, eject1: 1b, eject6: 0b}, componentEjector: {color0: -1, color1: -1, color2: -1, color3: -1, color4: -1, color5: -1, strictInput: 0b}, componentFrequency: {Security: {name: "Security", owner: [I; -265032353, -257276231, -1206336954, -524834293], publicFreq: 1b}}, componentSecurity: {owner: [I; -265032353, -257276231, -1206336954, -524834293], securityMode: 0}, componentUpgrade: {Items: [], upgrades: [{amount: 8, type: 0}, {amount: 8, type: 1}]}, controlType: 0, currentRedstone: 4, id: "mekanism:nutritional_liquifier", progress: 0, redstone: 0b, updateDelay: 0}},
        {pos: [5, 3, 2], state: "minecraft:air"},
        {pos: [5, 3, 3], state: "minecraft:air"},
        {pos: [5, 3, 4], state: "minecraft:air"},
        {pos: [5, 3, 5], state: "minecraft:air"},
        {pos: [5, 3, 6], state: "minecraft:air"},
        {pos: [5, 3, 7], state: "minecraft:air"},
        {pos: [5, 3, 8], state: "minecraft:air"},
        {pos: [5, 3, 9], state: "mekanism:ultimate_smelting_factory{active:false,facing:north,fluid_logged:empty}", nbt: {EnergyContainers: [{Container: 0b, stored: "900000"}], Items: [], activeState: 0b, componentConfig: {config0: {side0: 1, side1: 1, side2: 1, side3: 1, side4: 1, side5: 1}, config6: {side0: 1, side1: 1, side2: 4, side3: 8, side4: 1, side5: 1}, eject0: 0b, eject6: 0b}, componentEjector: {color0: -1, color1: -1, color2: -1, color3: -1, color4: -1, color5: -1, strictInput: 0b}, componentFrequency: {Security: {name: "Security", owner: [I; -265032353, -257276231, -1206336954, -524834293], publicFreq: 1b}}, componentSecurity: {owner: [I; -265032353, -257276231, -1206336954, -524834293], securityMode: 0}, componentUpgrade: {Items: [], upgrades: [{amount: 8, type: 0}, {amount: 8, type: 1}]}, controlType: 0, currentRedstone: 0, id: "mekanism:ultimate_smelting_factory", progress: [I; 0, 0, 0, 0, 0, 0, 0, 0, 0], redstone: 0b, sorting: 0b, updateDelay: 0}},
        {pos: [5, 3, 10], state: "minecraft:air"},
        {pos: [6, 3, 0], state: "minecraft:air"},
        {pos: [6, 3, 1], state: "minecraft:air"},
        {pos: [6, 3, 2], state: "minecraft:air"},
        {pos: [6, 3, 3], state: "minecraft:air"},
        {pos: [6, 3, 4], state: "minecraft:air"},
        {pos: [6, 3, 5], state: "minecraft:air"},
        {pos: [6, 3, 6], state: "minecraft:air"},
        {pos: [6, 3, 7], state: "minecraft:air"},
        {pos: [6, 3, 8], state: "minecraft:air"},
        {pos: [6, 3, 9], state: "mekanism:ultimate_enriching_factory{active:false,facing:north,fluid_logged:empty}", nbt: {EnergyContainers: [{Container: 0b, stored: "900000"}], Items: [], activeState: 0b, componentConfig: {config0: {side0: 1, side1: 1, side2: 1, side3: 1, side4: 1, side5: 1}, config6: {side0: 1, side1: 1, side2: 4, side3: 8, side4: 1, side5: 1}, eject0: 0b, eject6: 0b}, componentEjector: {color0: -1, color1: -1, color2: -1, color3: -1, color4: -1, color5: -1, strictInput: 0b}, componentFrequency: {Security: {name: "Security", owner: [I; -265032353, -257276231, -1206336954, -524834293], publicFreq: 1b}}, componentSecurity: {owner: [I; -265032353, -257276231, -1206336954, -524834293], securityMode: 0}, componentUpgrade: {Items: [], upgrades: [{amount: 8, type: 0}, {amount: 8, type: 1}]}, controlType: 0, currentRedstone: 0, id: "mekanism:ultimate_enriching_factory", progress: [I; 0, 0, 0, 0, 0, 0, 0, 0, 0], redstone: 0b, sorting: 0b, updateDelay: 0}},
        {pos: [6, 3, 10], state: "minecraft:air"},
        {pos: [7, 3, 0], state: "minecraft:air"},
        {pos: [7, 3, 1], state: "minecraft:air"},
        {pos: [7, 3, 2], state: "minecraft:air"},
        {pos: [7, 3, 3], state: "minecraft:air"},
        {pos: [7, 3, 4], state: "minecraft:air"},
        {pos: [7, 3, 5], state: "minecraft:air"},
        {pos: [7, 3, 6], state: "minecraft:air"},
        {pos: [7, 3, 7], state: "minecraft:air"},
        {pos: [7, 3, 8], state: "minecraft:air"},
        {pos: [7, 3, 9], state: "mekanism:ultimate_infusing_factory{active:false,facing:north,fluid_logged:empty}", nbt: {EnergyContainers: [{Container: 0b, stored: "900000"}], InfusionTanks: [], Items: [], activeState: 0b, componentConfig: {config0: {side0: 1, side1: 1, side2: 1, side3: 1, side4: 1, side5: 1}, config3: {side0: 1, side1: 1, side2: 4, side3: 1, side4: 1, side5: 1}, config6: {side0: 1, side1: 1, side2: 4, side3: 8, side4: 1, side5: 9}, eject0: 0b, eject3: 0b, eject6: 0b}, componentEjector: {color0: -1, color1: -1, color2: -1, color3: -1, color4: -1, color5: -1, strictInput: 0b}, componentFrequency: {Security: {name: "Security", owner: [I; -265032353, -257276231, -1206336954, -524834293], publicFreq: 1b}}, componentSecurity: {owner: [I; -265032353, -257276231, -1206336954, -524834293], securityMode: 0}, componentUpgrade: {Items: [], upgrades: [{amount: 8, type: 0}, {amount: 8, type: 1}]}, controlType: 0, currentRedstone: 0, id: "mekanism:ultimate_infusing_factory", progress: [I; 0, 0, 0, 0, 0, 0, 0, 0, 0], redstone: 0b, sorting: 0b, updateDelay: 0}},
        {pos: [7, 3, 10], state: "minecraft:air"},
        {pos: [8, 3, 0], state: "minecraft:air"},
        {pos: [8, 3, 1], state: "minecraft:air"},
        {pos: [8, 3, 2], state: "minecraft:air"},
        {pos: [8, 3, 3], state: "minecraft:air"},
        {pos: [8, 3, 4], state: "minecraft:air"},
        {pos: [8, 3, 5], state: "mekanism:qio_dashboard{active:true,facing:west,fluid_logged:empty}", nbt: {Items: [], activeState: 1b, color: 13, componentFrequency: {QIO: {name: "COD", owner: [I; -265032353, -257276231, -1206336954, -524834293], publicFreq: 1b}, Security: {name: "Security", owner: [I; -265032353, -257276231, -1206336954, -524834293], publicFreq: 1b}}, componentSecurity: {owner: [I; -265032353, -257276231, -1206336954, -524834293], securityMode: 0}, id: "mekanism:qio_dashboard", redstone: 0b, updateDelay: 0}},
        {pos: [8, 3, 6], state: "minecraft:air"},
        {pos: [8, 3, 7], state: "minecraft:air"},
        {pos: [8, 3, 8], state: "minecraft:air"},
        {pos: [8, 3, 9], state: "minecraft:air"},
        {pos: [8, 3, 10], state: "minecraft:air"},
        {pos: [9, 3, 0], state: "minecraft:air"},
        {pos: [9, 3, 1], state: "minecraft:air"},
        {pos: [9, 3, 2], state: "minecraft:air"},
        {pos: [9, 3, 3], state: "minecraft:air"},
        {pos: [9, 3, 4], state: "minecraft:air"},
        {pos: [9, 3, 5], state: "mekanism:qio_drive_array{active:true,facing:west,fluid_logged:empty}", nbt: {Items: [{Item: {Count: 1b, id: "mekanism:qio_drive_supermassive"}, Slot: 0b}], activeState: 1b, color: 13, componentFrequency: {QIO: {name: "COD", owner: [I; -265032353, -257276231, -1206336954, -524834293], publicFreq: 1b}, Security: {name: "Security", owner: [I; -265032353, -257276231, -1206336954, -524834293], publicFreq: 1b}}, componentSecurity: {owner: [I; -265032353, -257276231, -1206336954, -524834293], securityMode: 0}, id: "mekanism:qio_drive_array", redstone: 0b, updateDelay: 0}},
        {pos: [9, 3, 6], state: "minecraft:air"},
        {pos: [9, 3, 7], state: "minecraft:air"},
        {pos: [9, 3, 8], state: "minecraft:air"},
        {pos: [9, 3, 9], state: "minecraft:air"},
        {pos: [9, 3, 10], state: "minecraft:air"},
        {pos: [10, 3, 0], state: "minecraft:air"},
        {pos: [10, 3, 1], state: "minecraft:air"},
        {pos: [10, 3, 2], state: "minecraft:air"},
        {pos: [10, 3, 3], state: "minecraft:air"},
        {pos: [10, 3, 4], state: "minecraft:air"},
        {pos: [10, 3, 5], state: "minecraft:air"},
        {pos: [10, 3, 6], state: "minecraft:air"},
        {pos: [10, 3, 7], state: "minecraft:air"},
        {pos: [10, 3, 8], state: "minecraft:air"},
        {pos: [10, 3, 9], state: "minecraft:air"},
        {pos: [10, 3, 10], state: "minecraft:air"},
        {pos: [0, 4, 0], state: "minecraft:air"},
        {pos: [0, 4, 1], state: "minecraft:air"},
        {pos: [0, 4, 2], state: "minecraft:air"},
        {pos: [0, 4, 3], state: "minecraft:air"},
        {pos: [0, 4, 4], state: "minecraft:air"},
        {pos: [0, 4, 5], state: "minecraft:air"},
        {pos: [0, 4, 6], state: "minecraft:air"},
        {pos: [0, 4, 7], state: "minecraft:air"},
        {pos: [0, 4, 8], state: "minecraft:air"},
        {pos: [0, 4, 9], state: "minecraft:air"},
        {pos: [0, 4, 10], state: "minecraft:air"},
        {pos: [1, 4, 0], state: "minecraft:air"},
        {pos: [1, 4, 1], state: "minecraft:air"},
        {pos: [1, 4, 2], state: "minecraft:air"},
        {pos: [1, 4, 3], state: "mekanismadditions:gray_plastic_glow_stairs{facing:east,fluid_logged_extension:empty,half:bottom,shape:outer_right,waterlogged:false}"},
        {pos: [1, 4, 4], state: "mekanismadditions:gray_plastic_glow_stairs{facing:east,fluid_logged_extension:empty,half:bottom,shape:straight,waterlogged:false}"},
        {pos: [1, 4, 5], state: "mekanismadditions:gray_plastic_glow_stairs{facing:east,fluid_logged_extension:empty,half:bottom,shape:straight,waterlogged:false}"},
        {pos: [1, 4, 6], state: "mekanismadditions:gray_plastic_glow_stairs{facing:east,fluid_logged_extension:empty,half:bottom,shape:straight,waterlogged:false}"},
        {pos: [1, 4, 7], state: "mekanismadditions:gray_plastic_glow_stairs{facing:east,fluid_logged_extension:empty,half:bottom,shape:outer_left,waterlogged:false}"},
        {pos: [1, 4, 8], state: "minecraft:air"},
        {pos: [1, 4, 9], state: "minecraft:air"},
        {pos: [1, 4, 10], state: "minecraft:air"},
        {pos: [2, 4, 0], state: "minecraft:air"},
        {pos: [2, 4, 1], state: "minecraft:air"},
        {pos: [2, 4, 2], state: "minecraft:air"},
        {pos: [2, 4, 3], state: "mekanismadditions:light_gray_plastic_glow_stairs{facing:south,fluid_logged_extension:empty,half:bottom,shape:straight,waterlogged:false}"},
        {pos: [2, 4, 4], state: "mekanismadditions:light_gray_plastic_glow_stairs{facing:west,fluid_logged_extension:empty,half:top,shape:straight,waterlogged:false}"},
        {pos: [2, 4, 5], state: "mekanismadditions:light_gray_plastic_glow_stairs{facing:west,fluid_logged_extension:empty,half:top,shape:straight,waterlogged:false}"},
        {pos: [2, 4, 6], state: "mekanismadditions:light_gray_plastic_glow_stairs{facing:west,fluid_logged_extension:empty,half:top,shape:straight,waterlogged:false}"},
        {pos: [2, 4, 7], state: "mekanismadditions:light_gray_plastic_glow_stairs{facing:north,fluid_logged_extension:empty,half:bottom,shape:straight,waterlogged:false}"},
        {pos: [2, 4, 8], state: "minecraft:air"},
        {pos: [2, 4, 9], state: "minecraft:air"},
        {pos: [2, 4, 10], state: "minecraft:air"},
        {pos: [3, 4, 0], state: "minecraft:air"},
        {pos: [3, 4, 1], state: "minecraft:air"},
        {pos: [3, 4, 2], state: "minecraft:air"},
        {pos: [3, 4, 3], state: "minecraft:air"},
        {pos: [3, 4, 4], state: "minecraft:air"},
        {pos: [3, 4, 5], state: "minecraft:air"},
        {pos: [3, 4, 6], state: "minecraft:air"},
        {pos: [3, 4, 7], state: "minecraft:air"},
        {pos: [3, 4, 8], state: "minecraft:air"},
        {pos: [3, 4, 9], state: "minecraft:air"},
        {pos: [3, 4, 10], state: "minecraft:air"},
        {pos: [4, 4, 0], state: "minecraft:air"},
        {pos: [4, 4, 1], state: "minecraft:air"},
        {pos: [4, 4, 2], state: "minecraft:air"},
        {pos: [4, 4, 3], state: "minecraft:air"},
        {pos: [4, 4, 4], state: "minecraft:air"},
        {pos: [4, 4, 5], state: "minecraft:air"},
        {pos: [4, 4, 6], state: "minecraft:air"},
        {pos: [4, 4, 7], state: "minecraft:air"},
        {pos: [4, 4, 8], state: "minecraft:air"},
        {pos: [4, 4, 9], state: "minecraft:air"},
        {pos: [4, 4, 10], state: "minecraft:air"},
        {pos: [5, 4, 0], state: "mekanism:ultimate_logistical_transporter{fluid_logged:empty}", nbt: {color: -1, connection0: 0, connection1: 0, connection2: 0, connection3: 2, connection4: 0, connection5: 0, id: "mekanism:ultimate_logistical_transporter", redstone: 0b}},
        {pos: [5, 4, 1], state: "mekanism:creative_bin{active:false,facing:south}", nbt: {Items: [{Item: {Count: -1b, id: "minecraft:potato"}, SizeOverride: 2147483647, Slot: 0b}], activeState: 0b, componentFrequency: {}, currentRedstone: 15, id: "mekanism:creative_bin", redstone: 0b, updateDelay: 0}},
        {pos: [5, 4, 2], state: "minecraft:air"},
        {pos: [5, 4, 3], state: "minecraft:air"},
        {pos: [5, 4, 4], state: "minecraft:air"},
        {pos: [5, 4, 5], state: "minecraft:air"},
        {pos: [5, 4, 6], state: "minecraft:air"},
        {pos: [5, 4, 7], state: "minecraft:air"},
        {pos: [5, 4, 8], state: "minecraft:air"},
        {pos: [5, 4, 9], state: "minecraft:air"},
        {pos: [5, 4, 10], state: "minecraft:air"},
        {pos: [6, 4, 0], state: "minecraft:air"},
        {pos: [6, 4, 1], state: "minecraft:air"},
        {pos: [6, 4, 2], state: "minecraft:air"},
        {pos: [6, 4, 3], state: "minecraft:air"},
        {pos: [6, 4, 4], state: "minecraft:air"},
        {pos: [6, 4, 5], state: "minecraft:air"},
        {pos: [6, 4, 6], state: "minecraft:air"},
        {pos: [6, 4, 7], state: "minecraft:air"},
        {pos: [6, 4, 8], state: "minecraft:air"},
        {pos: [6, 4, 9], state: "minecraft:air"},
        {pos: [6, 4, 10], state: "minecraft:air"},
        {pos: [7, 4, 0], state: "minecraft:air"},
        {pos: [7, 4, 1], state: "minecraft:air"},
        {pos: [7, 4, 2], state: "minecraft:air"},
        {pos: [7, 4, 3], state: "minecraft:air"},
        {pos: [7, 4, 4], state: "minecraft:air"},
        {pos: [7, 4, 5], state: "minecraft:air"},
        {pos: [7, 4, 6], state: "minecraft:air"},
        {pos: [7, 4, 7], state: "minecraft:air"},
        {pos: [7, 4, 8], state: "minecraft:air"},
        {pos: [7, 4, 9], state: "minecraft:air"},
        {pos: [7, 4, 10], state: "minecraft:air"},
        {pos: [8, 4, 0], state: "minecraft:air"},
        {pos: [8, 4, 1], state: "minecraft:air"},
        {pos: [8, 4, 2], state: "minecraft:air"},
        {pos: [8, 4, 3], state: "minecraft:air"},
        {pos: [8, 4, 4], state: "minecraft:air"},
        {pos: [8, 4, 5], state: "minecraft:air"},
        {pos: [8, 4, 6], state: "minecraft:air"},
        {pos: [8, 4, 7], state: "minecraft:air"},
        {pos: [8, 4, 8], state: "minecraft:air"},
        {pos: [8, 4, 9], state: "minecraft:air"},
        {pos: [8, 4, 10], state: "minecraft:air"},
        {pos: [9, 4, 0], state: "minecraft:air"},
        {pos: [9, 4, 1], state: "minecraft:air"},
        {pos: [9, 4, 2], state: "minecraft:air"},
        {pos: [9, 4, 3], state: "minecraft:air"},
        {pos: [9, 4, 4], state: "minecraft:air"},
        {pos: [9, 4, 5], state: "minecraft:air"},
        {pos: [9, 4, 6], state: "minecraft:air"},
        {pos: [9, 4, 7], state: "minecraft:air"},
        {pos: [9, 4, 8], state: "minecraft:air"},
        {pos: [9, 4, 9], state: "minecraft:air"},
        {pos: [9, 4, 10], state: "minecraft:air"},
        {pos: [10, 4, 0], state: "minecraft:air"},
        {pos: [10, 4, 1], state: "minecraft:air"},
        {pos: [10, 4, 2], state: "minecraft:air"},
        {pos: [10, 4, 3], state: "minecraft:air"},
        {pos: [10, 4, 4], state: "minecraft:air"},
        {pos: [10, 4, 5], state: "minecraft:air"},
        {pos: [10, 4, 6], state: "minecraft:air"},
        {pos: [10, 4, 7], state: "minecraft:air"},
        {pos: [10, 4, 8], state: "minecraft:air"},
        {pos: [10, 4, 9], state: "minecraft:air"},
        {pos: [10, 4, 10], state: "minecraft:air"}
    ],
    entities: [],
    palette: [
        "minecraft:dirt",
        "mekanismadditions:black_reinforced_plastic",
        "mekanismadditions:white_reinforced_plastic",
        "mekanismadditions:white_plastic_glow",
        "mekanismadditions:gray_plastic_glow",
        "mekanismadditions:black_plastic_glow",
        "mekanismadditions:light_gray_plastic_glow",
        "mekanismadditions:magenta_plastic_transparent",
        "mekanismadditions:yellow_plastic_transparent",
        "mekanismadditions:light_gray_plastic_glow_stairs{facing:west,fluid_logged_extension:empty,half:bottom,shape:straight,waterlogged:false}",
        "mekanismadditions:light_gray_plastic_glow_stairs{facing:north,fluid_logged_extension:empty,half:bottom,shape:straight,waterlogged:false}",
        "mekanismadditions:light_gray_plastic_glow_stairs{facing:south,fluid_logged_extension:empty,half:bottom,shape:straight,waterlogged:false}",
        "minecraft:air",
        "adminshop:shop",
        "mekanismadditions:magenta_plastic_transparent_stairs{facing:east,fluid_logged_extension:empty,half:bottom,shape:inner_left,waterlogged:false}",
        "mekanismadditions:magenta_plastic_transparent_stairs{facing:east,fluid_logged_extension:empty,half:bottom,shape:straight,waterlogged:false}",
        "mekanismadditions:magenta_plastic_transparent_stairs{facing:east,fluid_logged_extension:empty,half:bottom,shape:inner_right,waterlogged:false}",
        "mekanismadditions:gray_plastic_glow_stairs{facing:west,fluid_logged_extension:empty,half:top,shape:straight,waterlogged:false}",
        "mekanismadditions:light_gray_plastic_glow_stairs{facing:west,fluid_logged_extension:empty,half:top,shape:straight,waterlogged:false}",
        "mekanismadditions:light_gray_plastic_glow_stairs{facing:north,fluid_logged_extension:empty,half:top,shape:straight,waterlogged:false}",
        "mekanismadditions:light_gray_plastic_glow_stairs{facing:south,fluid_logged_extension:empty,half:top,shape:straight,waterlogged:false}",
        "mekanismadditions:gray_plastic_glow_stairs{facing:east,fluid_logged_extension:empty,half:bottom,shape:outer_right,waterlogged:false}",
        "mekanismadditions:gray_plastic_glow_stairs{facing:east,fluid_logged_extension:empty,half:bottom,shape:straight,waterlogged:false}",
        "mekanismadditions:gray_plastic_glow_stairs{facing:east,fluid_logged_extension:empty,half:bottom,shape:outer_left,waterlogged:false}",
        "mekanism:ultimate_universal_cable{fluid_logged:empty}",
        "mekanism:creative_energy_cube{facing:south,fluid_logged:empty}",
        "mekanism:personal_chest{facing:east,fluid_logged:empty}",
        "mekanism:chargepad{active:false,facing:east,fluid_logged:empty}",
        "mekanism:ultimate_sawing_factory{active:false,facing:north,fluid_logged:empty}",
        "mekanism:ultimate_crushing_factory{active:false,facing:north,fluid_logged:empty}",
        "mekanism:ultimate_logistical_transporter{fluid_logged:empty}",
        "mekanism:nutritional_liquifier{active:false,facing:south}",
        "mekanism:ultimate_smelting_factory{active:false,facing:north,fluid_logged:empty}",
        "mekanism:ultimate_enriching_factory{active:false,facing:north,fluid_logged:empty}",
        "mekanism:ultimate_infusing_factory{active:false,facing:north,fluid_logged:empty}",
        "mekanism:qio_dashboard{active:true,facing:west,fluid_logged:empty}",
        "mekanism:qio_drive_array{active:true,facing:west,fluid_logged:empty}",
        "mekanism:creative_bin{active:false,facing:south}"
    ]
}