{
    DataVersion: 3465,
    size: [11, 15, 11],
    data: [
        {pos: [5, 0, 5], state: "minecraft:stone"},
        {pos: [4, 1, 4], state: "minecraft:stone"},
        {pos: [4, 1, 5], state: "minecraft:stone"},
        {pos: [4, 1, 6], state: "minecraft:stone"},
        {pos: [5, 1, 4], state: "minecraft:stone"},
        {pos: [5, 1, 5], state: "minecraft:bedrock"},
        {pos: [5, 1, 6], state: "minecraft:stone"},
        {pos: [6, 1, 4], state: "minecraft:stone"},
        {pos: [6, 1, 5], state: "minecraft:stone"},
        {pos: [6, 1, 6], state: "minecraft:stone"},
        {pos: [7, 1, 5], state: "minecraft:stone"},
        {pos: [2, 2, 4], state: "minecraft:stone"},
        {pos: [2, 2, 5], state: "minecraft:stone"},
        {pos: [2, 2, 6], state: "minecraft:stone"},
        {pos: [3, 2, 3], state: "minecraft:stone"},
        {pos: [3, 2, 4], state: "minecraft:stone"},
        {pos: [3, 2, 5], state: "minecraft:stone"},
        {pos: [3, 2, 6], state: "minecraft:stone"},
        {pos: [3, 2, 7], state: "minecraft:stone"},
        {pos: [4, 2, 2], state: "minecraft:stone"},
        {pos: [4, 2, 3], state: "minecraft:stone"},
        {pos: [4, 2, 4], state: "minecraft:stone"},
        {pos: [4, 2, 5], state: "minecraft:stone"},
        {pos: [4, 2, 6], state: "minecraft:stone"},
        {pos: [4, 2, 7], state: "minecraft:stone"},
        {pos: [4, 2, 8], state: "minecraft:stone"},
        {pos: [5, 2, 2], state: "minecraft:stone"},
        {pos: [5, 2, 3], state: "minecraft:stone"},
        {pos: [5, 2, 4], state: "minecraft:stone"},
        {pos: [5, 2, 5], state: "minecraft:stone"},
        {pos: [5, 2, 6], state: "minecraft:stone"},
        {pos: [5, 2, 7], state: "minecraft:stone"},
        {pos: [5, 2, 8], state: "minecraft:stone"},
        {pos: [6, 2, 2], state: "minecraft:stone"},
        {pos: [6, 2, 3], state: "minecraft:stone"},
        {pos: [6, 2, 4], state: "minecraft:stone"},
        {pos: [6, 2, 5], state: "minecraft:stone"},
        {pos: [6, 2, 6], state: "minecraft:stone"},
        {pos: [6, 2, 7], state: "minecraft:stone"},
        {pos: [6, 2, 8], state: "minecraft:stone"},
        {pos: [7, 2, 4], state: "minecraft:stone"},
        {pos: [7, 2, 5], state: "minecraft:stone"},
        {pos: [7, 2, 6], state: "minecraft:stone"},
        {pos: [7, 2, 7], state: "minecraft:stone"},
        {pos: [8, 2, 4], state: "minecraft:stone"},
        {pos: [8, 2, 5], state: "minecraft:stone"},
        {pos: [8, 2, 6], state: "minecraft:stone"},
        {pos: [1, 3, 5], state: "minecraft:stone"},
        {pos: [2, 3, 3], state: "minecraft:stone"},
        {pos: [2, 3, 4], state: "minecraft:stone"},
        {pos: [2, 3, 5], state: "minecraft:deepslate"},
        {pos: [2, 3, 6], state: "minecraft:stone"},
        {pos: [2, 3, 7], state: "minecraft:stone"},
        {pos: [3, 3, 2], state: "minecraft:stone"},
        {pos: [3, 3, 3], state: "minecraft:stone"},
        {pos: [3, 3, 4], state: "minecraft:deepslate"},
        {pos: [3, 3, 6], state: "minecraft:deepslate"},
        {pos: [3, 3, 7], state: "minecraft:stone"},
        {pos: [3, 3, 8], state: "minecraft:stone"},
        {pos: [4, 3, 2], state: "minecraft:stone"},
        {pos: [4, 3, 3], state: "minecraft:deepslate"},
        {pos: [4, 3, 4], state: "minecraft:stone"},
        {pos: [4, 3, 5], state: "minecraft:deepslate"},
        {pos: [4, 3, 6], state: "minecraft:stone"},
        {pos: [4, 3, 7], state: "minecraft:deepslate"},
        {pos: [4, 3, 8], state: "minecraft:stone"},
        {pos: [5, 3, 1], state: "minecraft:stone"},
        {pos: [5, 3, 2], state: "minecraft:deepslate"},
        {pos: [5, 3, 4], state: "minecraft:deepslate"},
        {pos: [5, 3, 5], state: "minecraft:stone"},
        {pos: [5, 3, 6], state: "minecraft:deepslate"},
        {pos: [5, 3, 8], state: "minecraft:deepslate"},
        {pos: [5, 3, 9], state: "minecraft:stone"},
        {pos: [6, 3, 2], state: "minecraft:stone"},
        {pos: [6, 3, 3], state: "minecraft:deepslate"},
        {pos: [6, 3, 4], state: "minecraft:stone"},
        {pos: [6, 3, 6], state: "minecraft:stone"},
        {pos: [6, 3, 7], state: "minecraft:deepslate"},
        {pos: [6, 3, 8], state: "minecraft:stone"},
        {pos: [7, 3, 2], state: "minecraft:stone"},
        {pos: [7, 3, 3], state: "minecraft:stone"},
        {pos: [7, 3, 4], state: "minecraft:deepslate"},
        {pos: [7, 3, 6], state: "minecraft:deepslate"},        
        {pos: [7, 3, 7], state: "minecraft:stone"},
        {pos: [7, 3, 8], state: "minecraft:stone"},
        {pos: [8, 3, 3], state: "minecraft:stone"},
        {pos: [8, 3, 4], state: "minecraft:stone"},
        {pos: [8, 3, 6], state: "minecraft:stone"},
        {pos: [8, 3, 7], state: "minecraft:stone"},
        {pos: [9, 3, 5], state: "minecraft:stone"},
        {pos: [1, 4, 4], state: "minecraft:stone"},
        {pos: [1, 4, 5], state: "minecraft:stone"},
        {pos: [1, 4, 6], state: "minecraft:stone"},
        {pos: [2, 4, 2], state: "minecraft:stone"},
        {pos: [2, 4, 3], state: "minecraft:stone"},
        {pos: [2, 4, 4], state: "minecraft:deepslate"},
        {pos: [2, 4, 6], state: "minecraft:deepslate"},
        {pos: [2, 4, 7], state: "minecraft:stone"},
        {pos: [2, 4, 8], state: "minecraft:stone"},
        {pos: [3, 4, 2], state: "minecraft:stone"},
        {pos: [3, 4, 3], state: "minecraft:deepslate"},
        {pos: [3, 4, 5], state: "minecraft:deepslate_redstone_ore"},
        {pos: [3, 4, 7], state: "minecraft:deepslate"},
        {pos: [3, 4, 8], state: "minecraft:stone"},
        {pos: [4, 4, 1], state: "minecraft:stone"},
        {pos: [4, 4, 2], state: "minecraft:deepslate"},
        {pos: [4, 4, 4], state: "minecraft:deepslate"},
        {pos: [4, 4, 6], state: "minecraft:deepslate"},
        {pos: [4, 4, 8], state: "minecraft:deepslate"},
        {pos: [4, 4, 9], state: "minecraft:stone"},
        {pos: [5, 4, 1], state: "minecraft:stone"},
        {pos: [5, 4, 3], state: "minecraft:deepslate_copper_ore"},
        {pos: [5, 4, 5], state: "minecraft:deepslate"},
        {pos: [5, 4, 7], state: "minecraft:deepslate_iron_ore"},
        {pos: [5, 4, 9], state: "minecraft:stone"},
        {pos: [6, 4, 1], state: "minecraft:stone"},
        {pos: [6, 4, 2], state: "minecraft:deepslate"},
        {pos: [6, 4, 4], state: "minecraft:deepslate"},
        {pos: [6, 4, 6], state: "minecraft:deepslate"},
        {pos: [6, 4, 8], state: "minecraft:deepslate"},
        {pos: [6, 4, 9], state: "minecraft:stone"},
        {pos: [7, 4, 2], state: "minecraft:stone"},
        {pos: [7, 4, 3], state: "minecraft:deepslate"},
        {pos: [7, 4, 5], state: "minecraft:deepslate_gold_ore"},
        {pos: [7, 4, 7], state: "minecraft:deepslate"},
        {pos: [7, 4, 8], state: "minecraft:stone"},
        {pos: [8, 4, 2], state: "minecraft:stone"},
        {pos: [8, 4, 3], state: "minecraft:stone"},
        {pos: [8, 4, 4], state: "minecraft:deepslate"},
        {pos: [8, 4, 6], state: "minecraft:deepslate"},
        {pos: [8, 4, 7], state: "minecraft:stone"},
        {pos: [8, 4, 8], state: "minecraft:stone"},
        {pos: [9, 4, 4], state: "minecraft:stone"},
        {pos: [9, 4, 5], state: "minecraft:stone"},
        {pos: [9, 4, 6], state: "minecraft:stone"},
        {pos: [0, 5, 4], state: "minecraft:stone"},
        {pos: [0, 5, 5], state: "minecraft:stone"},
        {pos: [0, 5, 6], state: "minecraft:stone"},
        {pos: [1, 5, 2], state: "minecraft:stone"},
        {pos: [1, 5, 3], state: "minecraft:stone"},
        {pos: [1, 5, 4], state: "minecraft:stone"},
        {pos: [1, 5, 5], state: "minecraft:stone"},
        {pos: [1, 5, 6], state: "minecraft:stone"},
        {pos: [1, 5, 7], state: "minecraft:stone"},
        {pos: [1, 5, 8], state: "minecraft:stone"},
        {pos: [2, 5, 1], state: "minecraft:stone"},
        {pos: [2, 5, 2], state: "minecraft:stone"},
        {pos: [2, 5, 3], state: "minecraft:stone"},
        {pos: [2, 5, 4], state: "minecraft:stone"},
        {pos: [2, 5, 5], state: "minecraft:deepslate"},
        {pos: [2, 5, 6], state: "minecraft:stone"},
        {pos: [2, 5, 7], state: "minecraft:stone"},
        {pos: [2, 5, 8], state: "minecraft:stone"},
        {pos: [2, 5, 9], state: "minecraft:stone"},
        {pos: [3, 5, 1], state: "minecraft:stone"},
        {pos: [3, 5, 2], state: "minecraft:stone"},
        {pos: [3, 5, 2], state: "minecraft:stone"},
        {pos: [3, 5, 3], state: "minecraft:stone"},         
        {pos: [3, 5, 4], state: "minecraft:deepslate"},
        {pos: [3, 5, 6], state: "minecraft:deepslate"},
        {pos: [3, 5, 7], state: "minecraft:stone"},
        {pos: [3, 5, 8], state: "minecraft:stone"},
        {pos: [3, 5, 9], state: "minecraft:stone"},
        {pos: [4, 5, 0], state: "minecraft:stone"},
        {pos: [4, 5, 1], state: "minecraft:stone"},
        {pos: [4, 5, 2], state: "minecraft:stone"},
        {pos: [4, 5, 3], state: "minecraft:deepslate"},
        {pos: [4, 5, 4], state: "minecraft:andesite"},
        {pos: [4, 5, 5], state: "minecraft:deepslate"},
        {pos: [4, 5, 6], state: "minecraft:andesite"},
        {pos: [4, 5, 7], state: "minecraft:deepslate"},
        {pos: [4, 5, 8], state: "minecraft:stone"},
        {pos: [4, 5, 9], state: "minecraft:stone"},
        {pos: [4, 5, 10], state: "minecraft:stone"},
        {pos: [5, 5, 0], state: "minecraft:stone"},
        {pos: [5, 5, 1], state: "minecraft:stone"},
        {pos: [5, 5, 2], state: "minecraft:deepslate"},
        {pos: [5, 5, 4], state: "minecraft:deepslate"},
        {pos: [5, 5, 5], state: "minecraft:andesite"},
        {pos: [5, 5, 6], state: "minecraft:deepslate"},
        {pos: [5, 5, 8], state: "minecraft:deepslate"},
        {pos: [5, 5, 9], state: "minecraft:stone"},
        {pos: [5, 5, 10], state: "minecraft:stone"},
        {pos: [6, 5, 0], state: "minecraft:stone"},
        {pos: [6, 5, 1], state: "minecraft:stone"},
        {pos: [6, 5, 2], state: "minecraft:stone"},
        {pos: [6, 5, 3], state: "minecraft:deepslate"},
        {pos: [6, 5, 4], state: "minecraft:andesite"},
        {pos: [6, 5, 5], state: "minecraft:deepslate"},
        {pos: [6, 5, 6], state: "minecraft:andesite"},
        {pos: [6, 5, 7], state: "minecraft:deepslate"},
        {pos: [6, 5, 8], state: "minecraft:stone"},
        {pos: [6, 5, 9], state: "minecraft:stone"},
        {pos: [6, 5, 10], state: "minecraft:stone"},
        {pos: [7, 5, 1], state: "minecraft:stone"},
        {pos: [7, 5, 2], state: "minecraft:stone"},
        {pos: [7, 5, 3], state: "minecraft:stone"},
        {pos: [7, 5, 4], state: "minecraft:deepslate"},
        {pos: [7, 5, 6], state: "minecraft:deepslate"},
        {pos: [7, 5, 7], state: "minecraft:stone"},
        {pos: [7, 5, 8], state: "minecraft:stone"},
        {pos: [7, 5, 9], state: "minecraft:stone"},
        {pos: [8, 5, 1], state: "minecraft:stone"},
        {pos: [8, 5, 2], state: "minecraft:stone"},
        {pos: [8, 5, 3], state: "minecraft:stone"},
        {pos: [8, 5, 4], state: "minecraft:stone"},
        {pos: [8, 5, 5], state: "minecraft:deepslate"},
        {pos: [8, 5, 6], state: "minecraft:stone"},
        {pos: [8, 5, 7], state: "minecraft:stone"},
        {pos: [8, 5, 8], state: "minecraft:stone"},
        {pos: [8, 5, 9], state: "minecraft:stone"},
        {pos: [9, 5, 2], state: "minecraft:stone"},
        {pos: [9, 5, 3], state: "minecraft:stone"},
        {pos: [9, 5, 4], state: "minecraft:stone"},
        {pos: [9, 5, 5], state: "minecraft:stone"},
        {pos: [9, 5, 6], state: "minecraft:stone"},
        {pos: [9, 5, 7], state: "minecraft:stone"},
        {pos: [9, 5, 8], state: "minecraft:stone"},
        {pos: [10, 5, 4], state: "minecraft:stone"},
        {pos: [10, 5, 5], state: "minecraft:stone"},
        {pos: [10, 5, 6], state: "minecraft:stone"},
        {pos: [0, 6, 3], state: "minecraft:dirt"},
        {pos: [0, 6, 4], state: "minecraft:dirt"},
        {pos: [0, 6, 5], state: "minecraft:dirt"},
        {pos: [0, 6, 6], state: "minecraft:dirt"},
        {pos: [0, 6, 7], state: "minecraft:dirt"},
        {pos: [1, 6, 2], state: "minecraft:dirt"},
        {pos: [1, 6, 3], state: "minecraft:dirt"},
        {pos: [1, 6, 4], state: "minecraft:dirt"},
        {pos: [1, 6, 5], state: "minecraft:dirt"},
        {pos: [1, 6, 6], state: "minecraft:dirt"},
        {pos: [1, 6, 7], state: "minecraft:dirt"},
        {pos: [1, 6, 8], state: "minecraft:dirt"},
        {pos: [2, 6, 1], state: "minecraft:dirt"},
        {pos: [2, 6, 2], state: "minecraft:stone"},
        {pos: [2, 6, 3], state: "minecraft:stone"},
        {pos: [2, 6, 4], state: "minecraft:dirt"},
        {pos: [2, 6, 5], state: "minecraft:stone"},
        {pos: [2, 6, 6], state: "minecraft:stone"},
        {pos: [2, 6, 7], state: "minecraft:dirt"},
        {pos: [2, 6, 8], state: "minecraft:stone"},
        {pos: [2, 6, 9], state: "minecraft:dirt"},
        {pos: [3, 6, 0], state: "minecraft:dirt"},
        {pos: [3, 6, 1], state: "minecraft:dirt"},
        {pos: [3, 6, 2], state: "minecraft:stone"},
        {pos: [3, 6, 3], state: "minecraft:stone"},        
        {pos: [3, 6, 4], state: "minecraft:stone"},
        {pos: [3, 6, 5], state: "minecraft:deepslate"},
        {pos: [3, 6, 6], state: "minecraft:stone"},
        {pos: [3, 6, 7], state: "minecraft:stone"},
        {pos: [3, 6, 8], state: "minecraft:stone"},
        {pos: [3, 6, 9], state: "minecraft:dirt"},
        {pos: [3, 6, 10], state: "minecraft:dirt"},
        {pos: [4, 6, 0], state: "minecraft:dirt"},
        {pos: [4, 6, 1], state: "minecraft:stone"},
        {pos: [4, 6, 2], state: "minecraft:stone"},
        {pos: [4, 6, 3], state: "minecraft:stone"},
        {pos: [4, 6, 4], state: "minecraft:andesite"},
        {pos: [4, 6, 5], state: "minecraft:andesite"},
        {pos: [4, 6, 6], state: "minecraft:andesite"},
        {pos: [4, 6, 7], state: "minecraft:stone"},
        {pos: [4, 6, 8], state: "minecraft:stone"},
        {pos: [4, 6, 9], state: "minecraft:stone"},
        {pos: [4, 6, 10], state: "minecraft:dirt"},
        {pos: [5, 6, 0], state: "minecraft:dirt"},
        {pos: [5, 6, 1], state: "minecraft:stone"},
        {pos: [5, 6, 2], state: "minecraft:stone"},
        {pos: [5, 6, 3], state: "minecraft:deepslate"},
        {pos: [5, 6, 4], state: "minecraft:andesite"},
        {pos: [5, 6, 5], state: "minecraft:andesite"},
        {pos: [5, 6, 6], state: "minecraft:andesite"},
        {pos: [5, 6, 7], state: "minecraft:deepslate"},
        {pos: [5, 6, 8], state: "minecraft:stone"},
        {pos: [5, 6, 9], state: "minecraft:stone"},
        {pos: [5, 6, 10], state: "minecraft:dirt"},
        {pos: [6, 6, 0], state: "minecraft:dirt"},
        {pos: [6, 6, 1], state: "minecraft:stone"},
        {pos: [6, 6, 2], state: "minecraft:stone"},
        {pos: [6, 6, 3], state: "minecraft:stone"},
        {pos: [6, 6, 4], state: "minecraft:andesite"},
        {pos: [6, 6, 5], state: "minecraft:andesite"},
        {pos: [6, 6, 6], state: "minecraft:andesite"},
        {pos: [6, 6, 7], state: "minecraft:stone"},
        {pos: [6, 6, 8], state: "minecraft:stone"},
        {pos: [6, 6, 9], state: "minecraft:stone"},
        {pos: [6, 6, 10], state: "minecraft:dirt"},
        {pos: [7, 6, 0], state: "minecraft:dirt"},
        {pos: [7, 6, 1], state: "minecraft:dirt"},
        {pos: [7, 6, 2], state: "minecraft:stone"},
        {pos: [7, 6, 3], state: "minecraft:stone"},
        {pos: [7, 6, 4], state: "minecraft:stone"},
        {pos: [7, 6, 5], state: "minecraft:deepslate"},
        {pos: [7, 6, 6], state: "minecraft:stone"},
        {pos: [7, 6, 7], state: "minecraft:stone"},
        {pos: [7, 6, 8], state: "minecraft:stone"},
        {pos: [7, 6, 9], state: "minecraft:dirt"},
        {pos: [7, 6, 10], state: "minecraft:dirt"},
        {pos: [8, 6, 1], state: "minecraft:dirt"},
        {pos: [8, 6, 2], state: "minecraft:stone"},
        {pos: [8, 6, 3], state: "minecraft:stone"},
        {pos: [8, 6, 4], state: "minecraft:stone"},
        {pos: [8, 6, 5], state: "minecraft:stone"},
        {pos: [8, 6, 6], state: "minecraft:stone"},
        {pos: [8, 6, 7], state: "minecraft:stone"},
        {pos: [8, 6, 8], state: "minecraft:stone"},
        {pos: [8, 6, 9], state: "minecraft:dirt"},
        {pos: [9, 6, 2], state: "minecraft:dirt"},
        {pos: [9, 6, 3], state: "minecraft:dirt"},
        {pos: [9, 6, 4], state: "minecraft:stone"},
        {pos: [9, 6, 5], state: "minecraft:stone"},
        {pos: [9, 6, 6], state: "minecraft:stone"},
        {pos: [9, 6, 7], state: "minecraft:dirt"},
        {pos: [9, 6, 8], state: "minecraft:dirt"},
        {pos: [10, 6, 3], state: "minecraft:dirt"},
        {pos: [10, 6, 4], state: "minecraft:dirt"},
        {pos: [10, 6, 5], state: "minecraft:dirt"},
        {pos: [10, 6, 6], state: "minecraft:dirt"},
        {pos: [10, 6, 7], state: "minecraft:dirt"},
        {pos: [0, 7, 3], state: "minecraft:grass_block{snowy:false}"},
        {pos: [0, 7, 4], state: "minecraft:grass_block{snowy:false}"},
        {pos: [0, 7, 5], state: "minecraft:grass_block{snowy:false}"},
        {pos: [0, 7, 6], state: "minecraft:grass_block{snowy:false}"},
        {pos: [0, 7, 7], state: "minecraft:grass_block{snowy:false}"},
        {pos: [1, 7, 2], state: "minecraft:grass_block{snowy:false}"},
        {pos: [1, 7, 3], state: "minecraft:grass_block{snowy:false}"},
        {pos: [1, 7, 4], state: "minecraft:grass_block{snowy:false}"},
        {pos: [1, 7, 5], state: "minecraft:water{level:0}"},
        {pos: [1, 7, 6], state: "minecraft:grass_block{snowy:false}"},
        {pos: [1, 7, 7], state: "minecraft:grass_block{snowy:false}"},
        {pos: [1, 7, 8], state: "minecraft:grass_block{snowy:false}"},
        {pos: [2, 7, 1], state: "minecraft:grass_block{snowy:false}"},
        {pos: [2, 7, 2], state: "minecraft:grass_block{snowy:false}"},
        {pos: [2, 7, 3], state: "minecraft:grass_block{snowy:false}"},
        {pos: [2, 7, 4], state: "minecraft:grass_block{snowy:false}"},
        {pos: [2, 7, 5], state: "minecraft:grass_block{snowy:false}"},
        {pos: [2, 7, 6], state: "minecraft:grass_block{snowy:false}"},
        {pos: [2, 7, 7], state: "minecraft:grass_block{snowy:false}"},
        {pos: [2, 7, 8], state: "minecraft:grass_block{snowy:false}"},
        {pos: [2, 7, 9], state: "minecraft:grass_block{snowy:false}"},
        {pos: [3, 7, 0], state: "minecraft:grass_block{snowy:false}"},
        {pos: [3, 7, 1], state: "minecraft:grass_block{snowy:false}"},
        {pos: [3, 7, 2], state: "minecraft:grass_block{snowy:false}"},
        {pos: [3, 7, 3], state: "minecraft:grass_block{snowy:false}"},
        {pos: [3, 7, 4], state: "minecraft:grass_block{snowy:false}"},
        {pos: [3, 7, 5], state: "minecraft:grass_block{snowy:false}"},
        {pos: [3, 7, 6], state: "minecraft:grass_block{snowy:false}"},
        {pos: [3, 7, 7], state: "minecraft:grass_block{snowy:false}"},
        {pos: [3, 7, 8], state: "minecraft:grass_block{snowy:false}"},
        {pos: [3, 7, 9], state: "minecraft:grass_block{snowy:false}"},
        {pos: [3, 7, 10], state: "minecraft:grass_block{snowy:false}"},
        {pos: [4, 7, 0], state: "minecraft:grass_block{snowy:false}"},
        {pos: [4, 7, 1], state: "minecraft:grass_block{snowy:false}"},
        {pos: [4, 7, 2], state: "minecraft:grass_block{snowy:false}"},
        {pos: [4, 7, 3], state: "minecraft:grass_block{snowy:false}"},
        {pos: [4, 7, 4], state: "minecraft:grass_block{snowy:false}"},
        {pos: [4, 7, 5], state: "minecraft:grass_block{snowy:false}"},
        {pos: [4, 7, 6], state: "minecraft:grass_block{snowy:false}"},
        {pos: [4, 7, 7], state: "minecraft:grass_block{snowy:false}"},
        {pos: [4, 7, 8], state: "minecraft:grass_block{snowy:false}"},
        {pos: [4, 7, 9], state: "minecraft:grass_block{snowy:false}"},
        {pos: [4, 7, 10], state: "minecraft:grass_block{snowy:false}"},
        {pos: [5, 7, 0], state: "minecraft:grass_block{snowy:false}"},
        {pos: [5, 7, 1], state: "minecraft:lava{level:0}"},
        {pos: [5, 7, 2], state: "minecraft:grass_block{snowy:false}"},
        {pos: [5, 7, 3], state: "minecraft:grass_block{snowy:false}"},
        {pos: [5, 7, 4], state: "minecraft:grass_block{snowy:false}"},
        {pos: [5, 7, 5], state: "ironchest:crystal_chest{facing:south,waterlogged:false}", nbt: {ForgeCaps: {}, Items: [{Count: 1b, Slot: 0b, id: "minecraft:white_bed"}, {Count: 1b, Slot: 1b, id: "minecraft:oak_sapling"}, {Count: 64b, Slot: 2b, id: "minecraft:bread"}], id: "ironchest:crystal_chest"}},
        {pos: [5, 7, 6], state: "minecraft:grass_block{snowy:false}"},
        {pos: [5, 7, 7], state: "minecraft:grass_block{snowy:false}"},
        {pos: [5, 7, 8], state: "minecraft:grass_block{snowy:false}"},
        {pos: [5, 7, 1], state: "minecraft:lava{level:0}"},
        {pos: [5, 7, 10], state: "minecraft:grass_block{snowy:false}"},
        {pos: [6, 7, 0], state: "minecraft:grass_block{snowy:false}"},
        {pos: [6, 7, 1], state: "minecraft:grass_block{snowy:false}"},
        {pos: [6, 7, 2], state: "minecraft:grass_block{snowy:false}"},
        {pos: [6, 7, 3], state: "minecraft:grass_block{snowy:false}"},
        {pos: [6, 7, 4], state: "minecraft:grass_block{snowy:false}"},
        {pos: [6, 7, 5], state: "minecraft:grass_block{snowy:false}"},
        {pos: [6, 7, 6], state: "minecraft:grass_block{snowy:false}"},
        {pos: [6, 7, 7], state: "minecraft:grass_block{snowy:false}"},
        {pos: [6, 7, 8], state: "minecraft:grass_block{snowy:false}"},
        {pos: [6, 7, 9], state: "minecraft:grass_block{snowy:false}"},
        {pos: [6, 7, 10], state: "minecraft:grass_block{snowy:false}"},
        {pos: [7, 7, 0], state: "minecraft:grass_block{snowy:false}"},
        {pos: [7, 7, 1], state: "minecraft:grass_block{snowy:false}"},
        {pos: [7, 7, 2], state: "minecraft:grass_block{snowy:false}"},
        {pos: [7, 7, 3], state: "minecraft:grass_block{snowy:false}"},
        {pos: [7, 7, 4], state: "minecraft:grass_block{snowy:false}"},
        {pos: [7, 7, 5], state: "minecraft:grass_block{snowy:false}"},
        {pos: [7, 7, 6], state: "minecraft:grass_block{snowy:false}"},
        {pos: [7, 7, 7], state: "minecraft:grass_block{snowy:false}"},
        {pos: [7, 7, 8], state: "minecraft:grass_block{snowy:false}"},
        {pos: [7, 7, 9], state: "minecraft:grass_block{snowy:false}"},
        {pos: [7, 7, 10], state: "minecraft:grass_block{snowy:false}"},
        {pos: [8, 7, 1], state: "minecraft:grass_block{snowy:false}"},
        {pos: [8, 7, 2], state: "minecraft:grass_block{snowy:false}"},
        {pos: [8, 7, 3], state: "minecraft:grass_block{snowy:false}"},
        {pos: [8, 7, 4], state: "minecraft:grass_block{snowy:false}"},
        {pos: [8, 7, 5], state: "minecraft:grass_block{snowy:false}"},
        {pos: [8, 7, 6], state: "minecraft:grass_block{snowy:false}"},
        {pos: [8, 7, 7], state: "minecraft:grass_block{snowy:false}"},
        {pos: [8, 7, 8], state: "minecraft:grass_block{snowy:false}"},
        {pos: [8, 7, 9], state: "minecraft:grass_block{snowy:false}"},
        {pos: [9, 7, 2], state: "minecraft:grass_block{snowy:false}"},
        {pos: [9, 7, 3], state: "minecraft:grass_block{snowy:false}"},
        {pos: [9, 7, 4], state: "minecraft:grass_block{snowy:false}"},
        {pos: [9, 7, 5], state: "minecraft:water{level:0}"},
        {pos: [9, 7, 6], state: "minecraft:grass_block{snowy:false}"},
        {pos: [9, 7, 7], state: "minecraft:grass_block{snowy:false}"},
        {pos: [9, 7, 8], state: "minecraft:grass_block{snowy:false}"},
        {pos: [10, 7, 3], state: "minecraft:grass_block{snowy:false}"},
        {pos: [10, 7, 4], state: "minecraft:grass_block{snowy:false}"},
        {pos: [10, 7, 5], state: "minecraft:grass_block{snowy:false}"},
        {pos: [10, 7, 6], state: "minecraft:grass_block{snowy:false}"},
        {pos: [10, 7, 7], state: "minecraft:grass_block{snowy:false}"},
        {pos: [5, 8, 5], state: "minecraft:oak_log{axis:y}"},
        {pos: [5, 9, 5], state: "minecraft:oak_log{axis:y}"},
        {pos: [5, 10, 5], state: "minecraft:oak_log{axis:y}"},
        {pos: [3, 11, 4], state: "minecraft:oak_leaves{distance:3,persistent:false,waterlogged:false}"},
        {pos: [3, 11, 5], state: "minecraft:oak_leaves{distance:2,persistent:false,waterlogged:false}"},
        {pos: [3, 11, 6], state: "minecraft:oak_leaves{distance:3,persistent:false,waterlogged:false}"},
        {pos: [4, 11, 3], state: "minecraft:oak_leaves{distance:3,persistent:false,waterlogged:false}"},
        {pos: [4, 11, 4], state: "minecraft:oak_leaves{distance:2,persistent:false,waterlogged:false}"},
        {pos: [4, 11, 5], state: "minecraft:oak_leaves{distance:1,persistent:false,waterlogged:false}"},
        {pos: [4, 11, 6], state: "minecraft:oak_leaves{distance:2,persistent:false,waterlogged:false}"},
        {pos: [4, 11, 7], state: "minecraft:oak_leaves{distance:3,persistent:false,waterlogged:false}"},
        {pos: [5, 11, 3], state: "minecraft:oak_leaves{distance:2,persistent:false,waterlogged:false}"},
        {pos: [5, 11, 4], state: "minecraft:oak_leaves{distance:1,persistent:false,waterlogged:false}"},
        {pos: [5, 11, 5], state: "minecraft:oak_log{axis:y}"},
        {pos: [5, 11, 6], state: "minecraft:oak_leaves{distance:1,persistent:false,waterlogged:false}"},
        {pos: [5, 11, 7], state: "minecraft:oak_leaves{distance:2,persistent:false,waterlogged:false}"},
        {pos: [6, 11, 3], state: "minecraft:oak_leaves{distance:3,persistent:false,waterlogged:false}"},
        {pos: [6, 11, 4], state: "minecraft:oak_leaves{distance:2,persistent:false,waterlogged:false}"},
        {pos: [6, 11, 5], state: "minecraft:oak_leaves{distance:1,persistent:false,waterlogged:false}"},
        {pos: [6, 11, 6], state: "minecraft:oak_leaves{distance:2,persistent:false,waterlogged:false}"},
        {pos: [6, 11, 7], state: "minecraft:oak_leaves{distance:3,persistent:false,waterlogged:false}"},
        {pos: [7, 11, 4], state: "minecraft:oak_leaves{distance:3,persistent:false,waterlogged:false}"},
        {pos: [7, 11, 5], state: "minecraft:oak_leaves{distance:2,persistent:false,waterlogged:false}"},
        {pos: [7, 11, 6], state: "minecraft:oak_leaves{distance:3,persistent:false,waterlogged:false}"},
        {pos: [7, 11, 7], state: "minecraft:oak_leaves{distance:4,persistent:false,waterlogged:false}"},
        {pos: [3, 12, 3], state: "minecraft:oak_leaves{distance:4,persistent:false,waterlogged:false}"},
        {pos: [3, 12, 4], state: "minecraft:oak_leaves{distance:3,persistent:false,waterlogged:false}"},
        {pos: [3, 12, 5], state: "minecraft:oak_leaves{distance:2,persistent:false,waterlogged:false}"},
        {pos: [3, 12, 6], state: "minecraft:oak_leaves{distance:3,persistent:false,waterlogged:false}"},
        {pos: [4, 12, 3], state: "minecraft:oak_leaves{distance:3,persistent:false,waterlogged:false}"},
        {pos: [4, 12, 4], state: "minecraft:oak_leaves{distance:2,persistent:false,waterlogged:false}"},
        {pos: [4, 12, 5], state: "minecraft:oak_leaves{distance:1,persistent:false,waterlogged:false}"},
        {pos: [4, 12, 6], state: "minecraft:oak_leaves{distance:2,persistent:false,waterlogged:false}"},
        {pos: [4, 12, 7], state: "minecraft:oak_leaves{distance:3,persistent:false,waterlogged:false}"},
        {pos: [5, 12, 3], state: "minecraft:oak_leaves{distance:2,persistent:false,waterlogged:false}"},
        {pos: [5, 12, 4], state: "minecraft:oak_leaves{distance:1,persistent:false,waterlogged:false}"},
        {pos: [5, 12, 5], state: "minecraft:oak_log{axis:y}"},
        {pos: [5, 12, 6], state: "minecraft:oak_leaves{distance:1,persistent:false,waterlogged:false}"},
        {pos: [5, 12, 7], state: "minecraft:oak_leaves{distance:2,persistent:false,waterlogged:false}"},
        {pos: [6, 12, 3], state: "minecraft:oak_leaves{distance:3,persistent:false,waterlogged:false}"},
        {pos: [6, 12, 4], state: "minecraft:oak_leaves{distance:2,persistent:false,waterlogged:false}"},
        {pos: [6, 12, 5], state: "minecraft:oak_leaves{distance:1,persistent:false,waterlogged:false}"},
        {pos: [6, 12, 6], state: "minecraft:oak_leaves{distance:2,persistent:false,waterlogged:false}"},
        {pos: [6, 12, 7], state: "minecraft:oak_leaves{distance:3,persistent:false,waterlogged:false}"},
        {pos: [7, 12, 3], state: "minecraft:oak_leaves{distance:4,persistent:false,waterlogged:false}"},
        {pos: [7, 12, 4], state: "minecraft:oak_leaves{distance:3,persistent:false,waterlogged:false}"},
        {pos: [7, 12, 5], state: "minecraft:oak_leaves{distance:2,persistent:false,waterlogged:false}"},
        {pos: [7, 12, 6], state: "minecraft:oak_leaves{distance:3,persistent:false,waterlogged:false}"},
        {pos: [7, 12, 7], state: "minecraft:oak_leaves{distance:4,persistent:false,waterlogged:false}"},
        {pos: [4, 13, 4], state: "minecraft:oak_leaves{distance:2,persistent:false,waterlogged:false}"},
        {pos: [4, 13, 5], state: "minecraft:oak_leaves{distance:1,persistent:false,waterlogged:false}"},
        {pos: [4, 13, 6], state: "minecraft:oak_leaves{distance:2,persistent:false,waterlogged:false}"},
        {pos: [5, 13, 4], state: "minecraft:oak_leaves{distance:1,persistent:false,waterlogged:false}"},
        {pos: [5, 13, 5], state: "minecraft:oak_log{axis:y}"},
        {pos: [5, 13, 6], state: "minecraft:oak_leaves{distance:1,persistent:false,waterlogged:false}"},
        {pos: [6, 13, 4], state: "minecraft:oak_leaves{distance:2,persistent:false,waterlogged:false}"},
        {pos: [6, 13, 5], state: "minecraft:oak_leaves{distance:1,persistent:false,waterlogged:false}"},
        {pos: [6, 13, 6], state: "minecraft:oak_leaves{distance:2,persistent:false,waterlogged:false}"},
        {pos: [4, 14, 5], state: "minecraft:oak_leaves{distance:2,persistent:false,waterlogged:false}"},
        {pos: [5, 14, 4], state: "minecraft:oak_leaves{distance:2,persistent:false,waterlogged:false}"},
        {pos: [5, 14, 5], state: "minecraft:oak_leaves{distance:1,persistent:false,waterlogged:false}"},
        {pos: [5, 14, 6], state: "minecraft:oak_leaves{distance:2,persistent:false,waterlogged:false}"},
        {pos: [6, 14, 5], state: "minecraft:oak_leaves{distance:2,persistent:false,waterlogged:false}"}
    ],
    entities: [],
    palette: [
        "minecraft:stone",
        "minecraft:bedrock",
        "minecraft:deepslate",
        "minecraft:andesite",
        "minecraft:deepslate_redstone_ore",
        "minecraft:deepslate_copper_ore",
        "minecraft:deepslate_iron_ore",
        "minecraft:deepslate_gold_ore",
        "minecraft:grass_block{snowy:false}",
        "minecraft:dirt",
        "minecraft:oak_log{axis:y}",
        "minecraft:oak_leaves{distance:3,persistent:false,waterlogged:false}",
        "minecraft:oak_leaves{distance:2,persistent:false,waterlogged:false}",
        "minecraft:oak_leaves{distance:1,persistent:false,waterlogged:false}",
        "minecraft:oak_leaves{distance:4,persistent:false,waterlogged:false}",
        "minecraft:water{level:0}",
        "minecraft:lava{level:0}",
        "ironchest:crystal_chest{facing:south,waterlogged:false}"
    ]
}